<?xml version="1.0"?>
<sdf version="1.6">
	<model name="whiskeye_robot" canonical_link="body">

		<!--
		<plugin
			filename="libwhiskeye_plugin.so"
			name="whiskeye_plugin::WhiskeyePlugin">
		</plugin>
		-->

		<plugin
			filename="gz-sim-imu-system"
			name="gz::sim::systems::Imu">
		</plugin>

		<plugin
			filename="gz-sim-pose-publisher-system"
			name="gz::sim::systems::PosePublisher">
			<publish_link_pose>false</publish_link_pose>
			<publish_sensor_pose>false</publish_sensor_pose>
			<publish_collision_pose>false</publish_collision_pose>
			<publish_visual_pose>false</publish_visual_pose>
			<publish_nested_model_pose>true</publish_nested_model_pose>
			<update_frequency>50</update_frequency>
		</plugin>

		<link name="body">

			<inertial>
				<pose>0 0 0.1 0 0 0</pose>
				<mass>10.0</mass>
				<inertia>
					<ixx>1.0</ixx>
					<ixy>0</ixy>
					<ixz>0</ixz>
					<iyy>1.0</iyy>
					<iyz>0</iyz>
					<izz>1.0</izz>
				</inertia>
			</inertial>

			<visual name="whiskeye_body_3_ec_22_large_1.dae_visual">
				<pose>0 0 0 0 0 0</pose>
				<geometry>
					<mesh>
						<uri>model://robot/mesh/hi/whiskeye_body_3_ec_22_large_1.dae</uri>
					</mesh>
				</geometry>
				<material>
					<ambient>0.1 0.1 0.1 1</ambient>
					<diffuse>0.1 0.1 0.1 1</diffuse>
					<specular>0.1 0.1 0.1 1</specular>
				</material>
			</visual>

			<visual name="whiskeye_body_3_wheel_3.dae_visual">
				<pose>0 0 0 0 0 0</pose>
				<geometry>
					<mesh>
						<uri>model://robot/mesh/hi/whiskeye_body_3_wheel_3.dae</uri>
					</mesh>
				</geometry>
				<material>
					<ambient>0.1 0.1 0.1 1</ambient>
					<diffuse>0.1 0.1 0.1 1</diffuse>
					<specular>0.1 0.1 0.1 1</specular>
				</material>
			</visual>

			<visual name="whiskeye_body_3_myomotordriverpcb_1.dae_visual">
				<pose>0 0 0 0 0 0</pose>
				<geometry>
					<mesh>
						<uri>model://robot/mesh/hi/whiskeye_body_3_myomotordriverpcb_1.dae</uri>
					</mesh>
				</geometry>
				<material>
					<ambient>0 1 0 1</ambient>
					<diffuse>0 1 0 1</diffuse>
					<specular>0 1 0 1</specular>
				</material>
			</visual>

			<visual name="whiskeye_body_3_wheel_2.dae_visual">
				<pose>0 0 0 0 0 0</pose>
				<geometry>
					<mesh>
						<uri>model://robot/mesh/hi/whiskeye_body_3_wheel_2.dae</uri>
					</mesh>
				</geometry>
				<material>
					<ambient>0.1 0.1 0.1 1</ambient>
					<diffuse>0.1 0.1 0.1 1</diffuse>
					<specular>0.1 0.1 0.1 1</specular>
				</material>
			</visual>

			<visual name="whiskeye_body_3_body_1.dae_visual">
				<pose>0 0 0 0 0 0</pose>
				<geometry>
					<mesh>
						<uri>model://robot/mesh/hi/whiskeye_body_3_body_1.dae</uri>
					</mesh>
				</geometry>
				<material>
					<ambient>1 1 1 1</ambient>
					<diffuse>1 1 1 1</diffuse>
					<specular>1 1 1 1</specular>
				</material>
			</visual>

			<visual name="whiskeye_body_3_wheel_1.dae_visual">
				<pose>0 0 0 0 0 0</pose>
				<geometry>
					<mesh>
						<uri>model://robot/mesh/hi/whiskeye_body_3_wheel_1.dae</uri>
					</mesh>
				</geometry>
				<material>
					<ambient>0.1 0.1 0.1 1</ambient>
					<diffuse>0.1 0.1 0.1 1</diffuse>
					<specular>0.1 0.1 0.1 1</specular>
				</material>
			</visual>

			<visual name="whiskeye_body_3_rl_d_30_101_50_01033_complete_1.dae_visual">
				<pose>0 0 0 0 0 0</pose>
				<geometry>
					<mesh>
						<uri>model://robot/mesh/hi/whiskeye_body_3_rl_d_30_101_50_01033_complete_1.dae</uri>
					</mesh>
				</geometry>
				<material>
					<ambient>0.1 0.1 0.1 1</ambient>
					<diffuse>0.1 0.1 0.1 1</diffuse>
					<specular>0.1 0.1 0.1 1</specular>
				</material>
			</visual>

			<visual name="whiskeye_body_3_host_pc_1.dae_visual">
				<pose>0 0 0 0 0 0</pose>
				<geometry>
					<mesh>
						<uri>model://robot/mesh/hi/whiskeye_body_3_host_pc_1.dae</uri>
					</mesh>
				</geometry>
				<material>
					<ambient>0.5 0.5 0.5 1</ambient>
					<diffuse>0.5 0.5 0.5 1</diffuse>
					<specular>0.5 0.5 0.5 1</specular>
				</material>
			</visual>

			<collision name="whiskeye_body_3_ec_22_large_1.dae_collision">
				<pose>0 0 0 0 0 0</pose>
				<geometry>
					<mesh>
						<uri>model://robot/mesh/lo/whiskeye_body_3_ec_22_large_1.dae</uri>
					</mesh>
				</geometry>
				<surface>
					<friction>
						<ode>
							<mu>0.1</mu>
							<mu2>0.1</mu2>
						</ode>
					</friction>
					<contact>
						<collide_without_contact>0</collide_without_contact>
					</contact>
				</surface>
			</collision>

			<collision name="whiskeye_body_3_wheel_3.dae_collision">
				<pose>0 0 0 0 0 0</pose>
				<geometry>
					<mesh>
						<uri>model://robot/mesh/lo/whiskeye_body_3_wheel_3.dae</uri>
					</mesh>
				</geometry>
				<surface>
					<friction>
						<ode>
							<mu>0.1</mu>
							<mu2>0.1</mu2>
						</ode>
					</friction>
					<contact>
						<collide_without_contact>0</collide_without_contact>
					</contact>
				</surface>
			</collision>

			<collision name="whiskeye_body_3_myomotordriverpcb_1.dae_collision">
				<pose>0 0 0 0 0 0</pose>
				<geometry>
					<mesh>
						<uri>model://robot/mesh/lo/whiskeye_body_3_myomotordriverpcb_1.dae</uri>
					</mesh>
				</geometry>
				<surface>
					<friction>
						<ode>
							<mu>0.1</mu>
							<mu2>0.1</mu2>
						</ode>
					</friction>
					<contact>
						<collide_without_contact>0</collide_without_contact>
					</contact>
				</surface>
			</collision>

			<collision name="whiskeye_body_3_wheel_2.dae_collision">
				<pose>0 0 0 0 0 0</pose>
				<geometry>
					<mesh>
						<uri>model://robot/mesh/lo/whiskeye_body_3_wheel_2.dae</uri>
					</mesh>
				</geometry>
				<surface>
					<friction>
						<ode>
							<mu>0.1</mu>
							<mu2>0.1</mu2>
						</ode>
					</friction>
					<contact>
						<collide_without_contact>0</collide_without_contact>
					</contact>
				</surface>
			</collision>

			<collision name="whiskeye_body_3_body_1.dae_collision">
				<pose>0 0 0 0 0 0</pose>
				<geometry>
					<mesh>
						<uri>model://robot/mesh/lo/whiskeye_body_3_body_1.dae</uri>
					</mesh>
				</geometry>
				<surface>
					<friction>
						<ode>
							<mu>0.1</mu>
							<mu2>0.1</mu2>
						</ode>
					</friction>
					<contact>
						<collide_without_contact>0</collide_without_contact>
					</contact>
				</surface>
			</collision>

			<collision name="whiskeye_body_3_wheel_1.dae_collision">
				<pose>0 0 0 0 0 0</pose>
				<geometry>
					<mesh>
						<uri>model://robot/mesh/lo/whiskeye_body_3_wheel_1.dae</uri>
					</mesh>
				</geometry>
				<surface>
					<friction>
						<ode>
							<mu>0.1</mu>
							<mu2>0.1</mu2>
						</ode>
					</friction>
					<contact>
						<collide_without_contact>0</collide_without_contact>
					</contact>
				</surface>
			</collision>

			<collision name="whiskeye_body_3_rl_d_30_101_50_01033_complete_1.dae_collision">
				<pose>0 0 0 0 0 0</pose>
				<geometry>
					<mesh>
						<uri>model://robot/mesh/lo/whiskeye_body_3_rl_d_30_101_50_01033_complete_1.dae</uri>
					</mesh>
				</geometry>
				<surface>
					<friction>
						<ode>
							<mu>0.1</mu>
							<mu2>0.1</mu2>
						</ode>
					</friction>
					<contact>
						<collide_without_contact>0</collide_without_contact>
					</contact>
				</surface>
			</collision>

			<collision name="whiskeye_body_3_host_pc_1.dae_collision">
				<pose>0 0 0 0 0 0</pose>
				<geometry>
					<mesh>
						<uri>model://robot/mesh/lo/whiskeye_body_3_host_pc_1.dae</uri>
					</mesh>
				</geometry>
				<surface>
					<friction>
						<ode>
							<mu>0.1</mu>
							<mu2>0.1</mu2>
						</ode>
					</friction>
					<contact>
						<collide_without_contact>0</collide_without_contact>
					</contact>
				</surface>
			</collision>

			<sensor name="imu_body" type="imu">
				<pose>0 0 0 0 0 0</pose>
				<always_on>1</always_on>
				<update_rate>50</update_rate>
				<visualize>false</visualize>
				<topic>/whiskeye/body/imu_body</topic>
			</sensor>

			<sensor name="cam2" type="camera">
				<pose>0.0 0.0 0.5 0 0 0</pose>
				<camera>
					<horizontal_fov>1.57</horizontal_fov>
					<image>
						<width>640</width>
						<height>480</height>
					</image>
					<clip>
						<near>0.001</near>
						<far>100</far>
					</clip>
				</camera>
				<always_on>1</always_on>
				<update_rate>5</update_rate>
				<visualize>false</visualize>
				<topic>/whiskeye/head/cam2/image_raw</topic>
			</sensor>

		</link>

		<joint type="revolute" name="body_neck">
			<pose>0.128651991487 -7.91168258729e-06 0.0798500105739 0 0 0</pose>
			<parent>body</parent>
			<child>neck</child>
			<axis>
				<xyz>0.0 0.0010000000475 0.0</xyz>
				<limit>
					<lower>0.0</lower>
					<upper>1.2217304763960306</upper>
				</limit>
				<dynamics>
					<friction>0.5</friction>
					<damping>0.5</damping>
				</dynamics>
			</axis>
		</joint>

		<plugin
			filename="gz-sim-joint-position-controller-system"
			name="gz::sim::systems::JointPositionController">
			<joint_name>body_neck</joint_name>
			<topic>/whiskeye/body_neck/pos_cmd</topic>
			<p_gain>250.0</p_gain>
			<i_gain>0.0</i_gain>
			<d_gain>25.0</d_gain>
			<i_max>0.0</i_max>
			<i_min>-0.0</i_min>
			<cmd_max>250.0</cmd_max>
			<cmd_min>-250.0</cmd_min>
		</plugin>

		<link name="neck">
			<inertial>
				<pose>0.144152000546 -8.86440284376e-06 0.203515514731 0 0 0</pose>
				<mass>0.5</mass>
				<inertia>
					<ixx>0.05</ixx>
					<ixy>0</ixy>
					<ixz>0</ixz>
					<iyy>0.05</iyy>
					<iyz>0</iyz>
					<izz>0.05</izz>
				</inertia>
			</inertial>
			<visual name="whiskeye_neck_2_ec_22_large_1.dae_visual">
				<pose>0 0 0 0 0 0</pose>
				<geometry>
					<mesh>
						<uri>model://robot/mesh/hi/whiskeye_neck_2_ec_22_large_1.dae</uri>
					</mesh>
				</geometry>
				<material>
					<ambient>0.1 0.1 0.1 1</ambient>
					<diffuse>0.1 0.1 0.1 1</diffuse>
					<specular>0.1 0.1 0.1 1</specular>
				</material>
			</visual>

			<visual name="whiskeye_neck_2_myomotordriverpcb_1.dae_visual">
				<pose>0 0 0 0 0 0</pose>
				<geometry>
					<mesh>
						<uri>model://robot/mesh/hi/whiskeye_neck_2_myomotordriverpcb_1.dae</uri>
					</mesh>
				</geometry>
				<material>
					<ambient>0 1 0 1</ambient>
					<diffuse>0 1 0 1</diffuse>
					<specular>0 1 0 1</specular>
				</material>
			</visual>

			<visual name="whiskeye_neck_2_neck_1.dae_visual">
				<pose>0 0 0 0 0 0</pose>
				<geometry>
					<mesh>
						<uri>model://robot/mesh/hi/whiskeye_neck_2_neck_1.dae</uri>
					</mesh>
				</geometry>
				<material>
					<ambient>0.5 0.5 0.5 1</ambient>
					<diffuse>0.5 0.5 0.5 1</diffuse>
					<specular>0.5 0.5 0.5 1</specular>
				</material>
			</visual>

			<visual name="whiskeye_neck_2_rl_d_20_101_38_01033_complete_1.dae_visual">
				<pose>0 0 0 0 0 0</pose>
				<geometry>
					<mesh>
						<uri>model://robot/mesh/hi/whiskeye_neck_2_rl_d_20_101_38_01033_complete_1.dae</uri>
					</mesh>
				</geometry>
				<material>
					<ambient>0.1 0.1 0.1 1</ambient>
					<diffuse>0.1 0.1 0.1 1</diffuse>
					<specular>0.1 0.1 0.1 1</specular>
				</material>
			</visual>


			<collision name="whiskeye_neck_2_ec_22_large_1.dae_collision">
				<pose>0 0 0 0 0 0</pose>
				<geometry>
					<mesh>
						<uri>model://robot/mesh/lo/whiskeye_neck_2_ec_22_large_1.dae</uri>
					</mesh>
				</geometry>
				<surface>
					<friction>
						<ode>
							<mu>0.1</mu>
							<mu2>0.1</mu2>
						</ode>
					</friction>
					<contact>
						<collide_without_contact>0</collide_without_contact>
					</contact>
				</surface>
			</collision>

			<collision name="whiskeye_neck_2_myomotordriverpcb_1.dae_collision">
				<pose>0 0 0 0 0 0</pose>
				<geometry>
					<mesh>
						<uri>model://robot/mesh/lo/whiskeye_neck_2_myomotordriverpcb_1.dae</uri>
					</mesh>
				</geometry>
				<surface>
					<friction>
						<ode>
							<mu>0.1</mu>
							<mu2>0.1</mu2>
						</ode>
					</friction>
					<contact>
						<collide_without_contact>0</collide_without_contact>
					</contact>
				</surface>
			</collision>

			<collision name="whiskeye_neck_2_neck_1.dae_collision">
				<pose>0 0 0 0 0 0</pose>
				<geometry>
					<mesh>
						<uri>model://robot/mesh/lo/whiskeye_neck_2_neck_1.dae</uri>
					</mesh>
				</geometry>
				<surface>
					<friction>
						<ode>
							<mu>0.1</mu>
							<mu2>0.1</mu2>
						</ode>
					</friction>
					<contact>
						<collide_without_contact>0</collide_without_contact>
					</contact>
				</surface>
			</collision>

			<collision name="whiskeye_neck_2_rl_d_20_101_38_01033_complete_1.dae_collision">
				<pose>0 0 0 0 0 0</pose>
				<geometry>
					<mesh>
						<uri>model://robot/mesh/lo/whiskeye_neck_2_rl_d_20_101_38_01033_complete_1.dae</uri>
					</mesh>
				</geometry>
				<surface>
					<friction>
						<ode>
							<mu>0.1</mu>
							<mu2>0.1</mu2>
						</ode>
					</friction>
					<contact>
						<collide_without_contact>0</collide_without_contact>
					</contact>
				</surface>
			</collision>

		</link>

		<joint type="revolute" name="neck_gmbl">
			<pose>0.159651994705 -9.81712400971e-06 0.327181011438 0 0 0</pose>
			<parent>neck</parent>
			<child>gmbl</child>
			<axis>
				<xyz>0.0 0.0010000000475 0.0</xyz>
				<limit>
					<lower>0.0</lower>
					<upper>2.0943951023931953</upper>
				</limit>
				<dynamics>
					<friction>0.5</friction>
					<damping>0.5</damping>
				</dynamics>
			</axis>
		</joint>

		<plugin
			filename="gz-sim-joint-position-controller-system"
			name="gz::sim::systems::JointPositionController">
			<joint_name>neck_gmbl</joint_name>
			<topic>/whiskeye/neck_gmbl/pos_cmd</topic>
			<p_gain>100.0</p_gain>
			<i_gain>0.0</i_gain>
			<d_gain>10.0</d_gain>
			<i_max>0.0</i_max>
			<i_min>-0.0</i_min>
			<cmd_max>50</cmd_max>
			<cmd_min>-50</cmd_min>
		</plugin>

		<link name="gmbl">
			<inertial>
				<pose>0.148526996374 -0.000217275621253 0.377306044102 0 0 0</pose>
				<mass>0.25</mass>
				<inertia>
					<ixx>0.025</ixx>
					<ixy>0</ixy>
					<ixz>0</ixz>
					<iyy>0.025</iyy>
					<iyz>0</iyz>
					<izz>0.025</izz>
				</inertia>
			</inertial>
			<visual name="whiskeye_gimbal_1_ec_22_medium_2.dae_visual">
				<pose>0 0 0 0 0 0</pose>
				<geometry>
					<mesh>
						<uri>model://robot/mesh/hi/whiskeye_gimbal_1_ec_22_medium_2.dae</uri>
					</mesh>
				</geometry>
				<material>
					<ambient>0.1 0.1 0.1 1</ambient>
					<diffuse>0.1 0.1 0.1 1</diffuse>
					<specular>0.1 0.1 0.1 1</specular>
				</material>
			</visual>

			<visual name="whiskeye_gimbal_1_myomotordriverpcb_2.dae_visual">
				<pose>0 0 0 0 0 0</pose>
				<geometry>
					<mesh>
						<uri>model://robot/mesh/hi/whiskeye_gimbal_1_myomotordriverpcb_2.dae</uri>
					</mesh>
				</geometry>
				<material>
					<ambient>0 1 0 1</ambient>
					<diffuse>0 1 0 1</diffuse>
					<specular>0 1 0 1</specular>
				</material>
			</visual>

			<visual name="whiskeye_gimbal_1_rl_d_20_101_38_01033_complete_1.dae_visual">
				<pose>0 0 0 0 0 0</pose>
				<geometry>
					<mesh>
						<uri>model://robot/mesh/hi/whiskeye_gimbal_1_rl_d_20_101_38_01033_complete_1.dae</uri>
					</mesh>
				</geometry>
				<material>
					<ambient>0.1 0.1 0.1 1</ambient>
					<diffuse>0.1 0.1 0.1 1</diffuse>
					<specular>0.1 0.1 0.1 1</specular>
				</material>
			</visual>

			<visual name="whiskeye_gimbal_1_gimbal_frame_1.dae_visual">
				<pose>0 0 0 0 0 0</pose>
				<geometry>
					<mesh>
						<uri>model://robot/mesh/hi/whiskeye_gimbal_1_gimbal_frame_1.dae</uri>
					</mesh>
				</geometry>
				<material>
					<ambient>0.5 0.5 0.5 1</ambient>
					<diffuse>0.5 0.5 0.5 1</diffuse>
					<specular>0.5 0.5 0.5 1</specular>
				</material>
			</visual>

			<collision name="whiskeye_gimbal_1_ec_22_medium_2.dae_collision">
				<pose>0 0 0 0 0 0</pose>
				<geometry>
					<mesh>
						<uri>model://robot/mesh/lo/whiskeye_gimbal_1_ec_22_medium_2.dae</uri>
					</mesh>
				</geometry>
				<surface>
					<friction>
						<ode>
							<mu>0.1</mu>
							<mu2>0.1</mu2>
						</ode>
					</friction>
					<contact>
						<collide_without_contact>0</collide_without_contact>
					</contact>
				</surface>
			</collision>

			<collision name="whiskeye_gimbal_1_myomotordriverpcb_2.dae_collision">
				<pose>0 0 0 0 0 0</pose>
				<geometry>
					<mesh>
						<uri>model://robot/mesh/lo/whiskeye_gimbal_1_myomotordriverpcb_2.dae</uri>
					</mesh>
				</geometry>
				<surface>
					<friction>
						<ode>
							<mu>0.1</mu>
							<mu2>0.1</mu2>
						</ode>
					</friction>
					<contact>
						<collide_without_contact>0</collide_without_contact>
					</contact>
				</surface>
			</collision>

			<collision name="whiskeye_gimbal_1_rl_d_20_101_38_01033_complete_1.dae_collision">
				<pose>0 0 0 0 0 0</pose>
				<geometry>
					<mesh>
						<uri>model://robot/mesh/lo/whiskeye_gimbal_1_rl_d_20_101_38_01033_complete_1.dae</uri>
					</mesh>
				</geometry>
				<surface>
					<friction>
						<ode>
							<mu>0.1</mu>
							<mu2>0.1</mu2>
						</ode>
					</friction>
					<contact>
						<collide_without_contact>0</collide_without_contact>
					</contact>
				</surface>
			</collision>

			<collision name="whiskeye_gimbal_1_gimbal_frame_1.dae_collision">
				<pose>0 0 0 0 0 0</pose>
				<geometry>
					<mesh>
						<uri>model://robot/mesh/lo/whiskeye_gimbal_1_gimbal_frame_1.dae</uri>
					</mesh>
				</geometry>
				<surface>
					<friction>
						<ode>
							<mu>0.1</mu>
							<mu2>0.1</mu2>
						</ode>
					</friction>
					<contact>
						<collide_without_contact>0</collide_without_contact>
					</contact>
				</surface>
			</collision>

		</link>

		<joint type="revolute" name="gmbl_head">
			<pose>0.137401998043 -0.000424734113039 0.427431046963 0 0 0</pose>
			<parent>gmbl</parent>
			<child>head</child>
			<axis>
				<xyz>-0.0010000000475 0.0 0.0</xyz>
				<limit>
					<lower>-1.5707963267948966</lower>
					<upper>1.5707963267948966</upper>
				</limit>
				<dynamics>
					<friction>0.5</friction>
					<damping>0.5</damping>
				</dynamics>
			</axis>
		</joint>

		<plugin
			filename="gz-sim-joint-position-controller-system"
			name="gz::sim::systems::JointPositionController">
			<joint_name>gmbl_head</joint_name>
			<topic>/whiskeye/gmbl_head/pos_cmd</topic>
			<p_gain>150.0</p_gain>
			<i_gain>0.0</i_gain>
			<d_gain>15.0</d_gain>
			<i_max>0.0</i_max>
			<i_min>-0.0</i_min>
			<cmd_max>75.0</cmd_max>
			<cmd_min>-75.0</cmd_min>
		</plugin>

		<link name="head">
			<inertial>
				<pose>0.137401992798 -0.000424734085798 0.527431030273 0 0 0</pose>
				<mass>0.5</mass>
				<inertia>
					<ixx>0.05</ixx>
					<ixy>0</ixy>
					<ixz>0</ixz>
					<iyy>0.05</iyy>
					<iyz>0</iyz>
					<izz>0.05</izz>
				</inertia>
			</inertial>
			<visual name="whiskeye_head_1_eyemount_yaw_3.dae_visual">
				<pose>0 0 0 0 0 0</pose>
				<geometry>
					<mesh>
						<uri>model://robot/mesh/hi/whiskeye_head_1_eyemount_yaw_3.dae</uri>
					</mesh>
				</geometry>
				<material>
					<ambient>1 1 1 1</ambient>
					<diffuse>1 1 1 1</diffuse>
					<specular>1 1 1 1</specular>
				</material>
			</visual>

			<visual name="whiskeye_head_1_micro_array_1_micro_array_vs2_1.dae_visual">
				<pose>0 0 0 0 0 0</pose>
				<geometry>
					<mesh>
						<uri>model://robot/mesh/hi/whiskeye_head_1_micro_array_1_micro_array_vs2_1.dae</uri>
					</mesh>
				</geometry>
				<material>
					<ambient>0.1 0.1 0.1 1</ambient>
					<diffuse>0.1 0.1 0.1 1</diffuse>
					<specular>0.1 0.1 0.1 1</specular>
				</material>
			</visual>

			<visual name="whiskeye_head_1_eyemount_elevation_1.dae_visual">
				<pose>0 0 0 0 0 0</pose>
				<geometry>
					<mesh>
						<uri>model://robot/mesh/hi/whiskeye_head_1_eyemount_elevation_1.dae</uri>
					</mesh>
				</geometry>
				<material>
					<ambient>1 1 1 1</ambient>
					<diffuse>1 1 1 1</diffuse>
					<specular>1 1 1 1</specular>
				</material>
			</visual>

			<visual name="whiskeye_head_1_pcb_head_1.dae_visual">
				<pose>0 0 0 0 0 0</pose>
				<geometry>
					<mesh>
						<uri>model://robot/mesh/hi/whiskeye_head_1_pcb_head_1.dae</uri>
					</mesh>
				</geometry>
				<material>
					<ambient>0 1 0 1</ambient>
					<diffuse>0 1 0 1</diffuse>
					<specular>0 1 0 1</specular>
				</material>
			</visual>

			<visual name="whiskeye_head_1_elp_camera_2.dae_visual">
				<pose>0 0 0 0 0 0</pose>
				<geometry>
					<mesh>
						<uri>model://robot/mesh/hi/whiskeye_head_1_elp_camera_2.dae</uri>
					</mesh>
				</geometry>
				<material>
					<ambient>1 1 0 1</ambient>
					<diffuse>1 1 0 1</diffuse>
					<specular>1 1 0 1</specular>
				</material>
			</visual>

			<visual name="whiskeye_head_1_micro_array_1_micro_array_mount_vs2_1.dae_visual">
				<pose>0 0 0 0 0 0</pose>
				<geometry>
					<mesh>
						<uri>model://robot/mesh/hi/whiskeye_head_1_micro_array_1_micro_array_mount_vs2_1.dae</uri>
					</mesh>
				</geometry>
				<material>
					<ambient>0.1 0.1 0.1 1</ambient>
					<diffuse>0.1 0.1 0.1 1</diffuse>
					<specular>0.1 0.1 0.1 1</specular>
				</material>
			</visual>

			<visual name="whiskeye_head_1_eyemount_camholder_reduced_2.dae_visual">
				<pose>0 0 0 0 0 0</pose>
				<geometry>
					<mesh>
						<uri>model://robot/mesh/hi/whiskeye_head_1_eyemount_camholder_reduced_2.dae</uri>
					</mesh>
				</geometry>
				<material>
					<ambient>1 1 1 1</ambient>
					<diffuse>1 1 1 1</diffuse>
					<specular>1 1 1 1</specular>
				</material>
			</visual>

			<visual name="whiskeye_head_1_row_mini_3_row_reduced_1.dae_visual">
				<pose>0 0 0 0 0 0</pose>
				<geometry>
					<mesh>
						<uri>model://robot/mesh/hi/whiskeye_head_1_row_mini_3_row_reduced_1.dae</uri>
					</mesh>
				</geometry>
				<material>
					<ambient>0 1 0 1</ambient>
					<diffuse>0 1 0 1</diffuse>
					<specular>0 1 0 1</specular>
				</material>
			</visual>

			<visual name="whiskeye_head_1_row_mini_4_row_reduced_1.dae_visual">
				<pose>0 0 0 0 0 0</pose>
				<geometry>
					<mesh>
						<uri>model://robot/mesh/hi/whiskeye_head_1_row_mini_4_row_reduced_1.dae</uri>
					</mesh>
				</geometry>
				<material>
					<ambient>0 1 0 1</ambient>
					<diffuse>0 1 0 1</diffuse>
					<specular>0 1 0 1</specular>
				</material>
			</visual>

			<visual name="whiskeye_head_1_eyemount_yaw_4.dae_visual">
				<pose>0 0 0 0 0 0</pose>
				<geometry>
					<mesh>
						<uri>model://robot/mesh/hi/whiskeye_head_1_eyemount_yaw_4.dae</uri>
					</mesh>
				</geometry>
				<material>
					<ambient>1 1 1 1</ambient>
					<diffuse>1 1 1 1</diffuse>
					<specular>1 1 1 1</specular>
				</material>
			</visual>

			<visual name="whiskeye_head_1_head_barebones_1.dae_visual">
				<pose>0 0 0 0 0 0</pose>
				<geometry>
					<mesh>
						<uri>model://robot/mesh/hi/whiskeye_head_1_head_barebones_1.dae</uri>
					</mesh>
				</geometry>
				<material>
					<ambient>1 1 1 1</ambient>
					<diffuse>1 1 1 1</diffuse>
					<specular>1 1 1 1</specular>
				</material>
			</visual>

			<visual name="whiskeye_head_1_row_mini_5_row_reduced_1.dae_visual">
				<pose>0 0 0 0 0 0</pose>
				<geometry>
					<mesh>
						<uri>model://robot/mesh/hi/whiskeye_head_1_row_mini_5_row_reduced_1.dae</uri>
					</mesh>
				</geometry>
				<material>
					<ambient>0 1 0 1</ambient>
					<diffuse>0 1 0 1</diffuse>
					<specular>0 1 0 1</specular>
				</material>
			</visual>

			<visual name="whiskeye_head_1_eyemount_elevation_2.dae_visual">
				<pose>0 0 0 0 0 0</pose>
				<geometry>
					<mesh>
						<uri>model://robot/mesh/hi/whiskeye_head_1_eyemount_elevation_2.dae</uri>
					</mesh>
				</geometry>
				<material>
					<ambient>1 1 1 1</ambient>
					<diffuse>1 1 1 1</diffuse>
					<specular>1 1 1 1</specular>
				</material>
			</visual>

			<visual name="whiskeye_head_1_elp_camera_1.dae_visual">
				<pose>0 0 0 0 0 0</pose>
				<geometry>
					<mesh>
						<uri>model://robot/mesh/hi/whiskeye_head_1_elp_camera_1.dae</uri>
					</mesh>
				</geometry>
				<material>
					<ambient>1 1 0 1</ambient>
					<diffuse>1 1 0 1</diffuse>
					<specular>1 1 0 1</specular>
				</material>
			</visual>

			<visual name="whiskeye_head_1_row_mini_2_row_reduced_1.dae_visual">
				<pose>0 0 0 0 0 0</pose>
				<geometry>
					<mesh>
						<uri>model://robot/mesh/hi/whiskeye_head_1_row_mini_2_row_reduced_1.dae</uri>
					</mesh>
				</geometry>
				<material>
					<ambient>0 1 0 1</ambient>
					<diffuse>0 1 0 1</diffuse>
					<specular>0 1 0 1</specular>
				</material>
			</visual>

			<visual name="whiskeye_head_1_pi_compute_1.dae_visual">
				<pose>0 0 0 0 0 0</pose>
				<geometry>
					<mesh>
						<uri>model://robot/mesh/hi/whiskeye_head_1_pi_compute_1.dae</uri>
					</mesh>
				</geometry>
				<material>
					<ambient>0 1 0 1</ambient>
					<diffuse>0 1 0 1</diffuse>
					<specular>0 1 0 1</specular>
				</material>
			</visual>

			<visual name="whiskeye_head_1_eyemount_camholder_reduced_1.dae_visual">
				<pose>0 0 0 0 0 0</pose>
				<geometry>
					<mesh>
						<uri>model://robot/mesh/hi/whiskeye_head_1_eyemount_camholder_reduced_1.dae</uri>
					</mesh>
				</geometry>
				<material>
					<ambient>1 1 1 1</ambient>
					<diffuse>1 1 1 1</diffuse>
					<specular>1 1 1 1</specular>
				</material>
			</visual>

			<visual name="whiskeye_head_1_row_mini_6_row_reduced_1.dae_visual">
				<pose>0 0 0 0 0 0</pose>
				<geometry>
					<mesh>
						<uri>model://robot/mesh/hi/whiskeye_head_1_row_mini_6_row_reduced_1.dae</uri>
					</mesh>
				</geometry>
				<material>
					<ambient>0 1 0 1</ambient>
					<diffuse>0 1 0 1</diffuse>
					<specular>0 1 0 1</specular>
				</material>
			</visual>

			<visual name="whiskeye_head_1_row_mini_1_row_reduced_1.dae_visual">
				<pose>0 0 0 0 0 0</pose>
				<geometry>
					<mesh>
						<uri>model://robot/mesh/hi/whiskeye_head_1_row_mini_1_row_reduced_1.dae</uri>
					</mesh>
				</geometry>
				<material>
					<ambient>0 1 0 1</ambient>
					<diffuse>0 1 0 1</diffuse>
					<specular>0 1 0 1</specular>
				</material>
			</visual>


			<collision name="whiskeye_head_1_eyemount_yaw_3.dae_collision">
				<pose>0 0 0 0 0 0</pose>
				<geometry>
					<mesh>
						<uri>model://robot/mesh/lo/whiskeye_head_1_eyemount_yaw_3.dae</uri>
					</mesh>
				</geometry>
				<surface>
					<friction>
						<ode>
							<mu>0.1</mu>
							<mu2>0.1</mu2>
						</ode>
					</friction>
					<contact>
						<collide_without_contact>0</collide_without_contact>
					</contact>
				</surface>
			</collision>

			<collision name="whiskeye_head_1_micro_array_1_micro_array_vs2_1.dae_collision">
				<pose>0 0 0 0 0 0</pose>
				<geometry>
					<mesh>
						<uri>model://robot/mesh/lo/whiskeye_head_1_micro_array_1_micro_array_vs2_1.dae</uri>
					</mesh>
				</geometry>
				<surface>
					<friction>
						<ode>
							<mu>0.1</mu>
							<mu2>0.1</mu2>
						</ode>
					</friction>
					<contact>
						<collide_without_contact>0</collide_without_contact>
					</contact>
				</surface>
			</collision>

			<collision name="whiskeye_head_1_eyemount_elevation_1.dae_collision">
				<pose>0 0 0 0 0 0</pose>
				<geometry>
					<mesh>
						<uri>model://robot/mesh/lo/whiskeye_head_1_eyemount_elevation_1.dae</uri>
					</mesh>
				</geometry>
				<surface>
					<friction>
						<ode>
							<mu>0.1</mu>
							<mu2>0.1</mu2>
						</ode>
					</friction>
					<contact>
						<collide_without_contact>0</collide_without_contact>
					</contact>
				</surface>
			</collision>

			<collision name="whiskeye_head_1_pcb_head_1.dae_collision">
				<pose>0 0 0 0 0 0</pose>
				<geometry>
					<mesh>
						<uri>model://robot/mesh/lo/whiskeye_head_1_pcb_head_1.dae</uri>
					</mesh>
				</geometry>
				<surface>
					<friction>
						<ode>
							<mu>0.1</mu>
							<mu2>0.1</mu2>
						</ode>
					</friction>
					<contact>
						<collide_without_contact>0</collide_without_contact>
					</contact>
				</surface>
			</collision>

			<collision name="whiskeye_head_1_elp_camera_2.dae_collision">
				<pose>0 0 0 0 0 0</pose>
				<geometry>
					<mesh>
						<uri>model://robot/mesh/lo/whiskeye_head_1_elp_camera_2.dae</uri>
					</mesh>
				</geometry>
				<surface>
					<friction>
						<ode>
							<mu>0.1</mu>
							<mu2>0.1</mu2>
						</ode>
					</friction>
					<contact>
						<collide_without_contact>0</collide_without_contact>
					</contact>
				</surface>
			</collision>

			<collision name="whiskeye_head_1_micro_array_1_micro_array_mount_vs2_1.dae_collision">
				<pose>0 0 0 0 0 0</pose>
				<geometry>
					<mesh>
						<uri>model://robot/mesh/lo/whiskeye_head_1_micro_array_1_micro_array_mount_vs2_1.dae</uri>
					</mesh>
				</geometry>
				<surface>
					<friction>
						<ode>
							<mu>0.1</mu>
							<mu2>0.1</mu2>
						</ode>
					</friction>
					<contact>
						<collide_without_contact>0</collide_without_contact>
					</contact>
				</surface>
			</collision>

			<collision name="whiskeye_head_1_eyemount_camholder_reduced_2.dae_collision">
				<pose>0 0 0 0 0 0</pose>
				<geometry>
					<mesh>
						<uri>model://robot/mesh/lo/whiskeye_head_1_eyemount_camholder_reduced_2.dae</uri>
					</mesh>
				</geometry>
				<surface>
					<friction>
						<ode>
							<mu>0.1</mu>
							<mu2>0.1</mu2>
						</ode>
					</friction>
					<contact>
						<collide_without_contact>0</collide_without_contact>
					</contact>
				</surface>
			</collision>

			<collision name="whiskeye_head_1_row_mini_3_row_reduced_1.dae_collision">
				<pose>0 0 0 0 0 0</pose>
				<geometry>
					<mesh>
						<uri>model://robot/mesh/lo/whiskeye_head_1_row_mini_3_row_reduced_1.dae</uri>
					</mesh>
				</geometry>
				<surface>
					<friction>
						<ode>
							<mu>0.1</mu>
							<mu2>0.1</mu2>
						</ode>
					</friction>
					<contact>
						<collide_without_contact>0</collide_without_contact>
					</contact>
				</surface>
			</collision>

			<collision name="whiskeye_head_1_row_mini_4_row_reduced_1.dae_collision">
				<pose>0 0 0 0 0 0</pose>
				<geometry>
					<mesh>
						<uri>model://robot/mesh/lo/whiskeye_head_1_row_mini_4_row_reduced_1.dae</uri>
					</mesh>
				</geometry>
				<surface>
					<friction>
						<ode>
							<mu>0.1</mu>
							<mu2>0.1</mu2>
						</ode>
					</friction>
					<contact>
						<collide_without_contact>0</collide_without_contact>
					</contact>
				</surface>
			</collision>

			<collision name="whiskeye_head_1_eyemount_yaw_4.dae_collision">
				<pose>0 0 0 0 0 0</pose>
				<geometry>
					<mesh>
						<uri>model://robot/mesh/lo/whiskeye_head_1_eyemount_yaw_4.dae</uri>
					</mesh>
				</geometry>
				<surface>
					<friction>
						<ode>
							<mu>0.1</mu>
							<mu2>0.1</mu2>
						</ode>
					</friction>
					<contact>
						<collide_without_contact>0</collide_without_contact>
					</contact>
				</surface>
			</collision>

			<collision name="whiskeye_head_1_head_barebones_1.dae_collision">
				<pose>0 0 0 0 0 0</pose>
				<geometry>
					<mesh>
						<uri>model://robot/mesh/lo/whiskeye_head_1_head_barebones_1.dae</uri>
					</mesh>
				</geometry>
				<surface>
					<friction>
						<ode>
							<mu>0.1</mu>
							<mu2>0.1</mu2>
						</ode>
					</friction>
					<contact>
						<collide_without_contact>0</collide_without_contact>
					</contact>
				</surface>
			</collision>

			<collision name="whiskeye_head_1_row_mini_5_row_reduced_1.dae_collision">
				<pose>0 0 0 0 0 0</pose>
				<geometry>
					<mesh>
						<uri>model://robot/mesh/lo/whiskeye_head_1_row_mini_5_row_reduced_1.dae</uri>
					</mesh>
				</geometry>
				<surface>
					<friction>
						<ode>
							<mu>0.1</mu>
							<mu2>0.1</mu2>
						</ode>
					</friction>
					<contact>
						<collide_without_contact>0</collide_without_contact>
					</contact>
				</surface>
			</collision>

			<collision name="whiskeye_head_1_eyemount_elevation_2.dae_collision">
				<pose>0 0 0 0 0 0</pose>
				<geometry>
					<mesh>
						<uri>model://robot/mesh/lo/whiskeye_head_1_eyemount_elevation_2.dae</uri>
					</mesh>
				</geometry>
				<surface>
					<friction>
						<ode>
							<mu>0.1</mu>
							<mu2>0.1</mu2>
						</ode>
					</friction>
					<contact>
						<collide_without_contact>0</collide_without_contact>
					</contact>
				</surface>
			</collision>

			<collision name="whiskeye_head_1_elp_camera_1.dae_collision">
				<pose>0 0 0 0 0 0</pose>
				<geometry>
					<mesh>
						<uri>model://robot/mesh/lo/whiskeye_head_1_elp_camera_1.dae</uri>
					</mesh>
				</geometry>
				<surface>
					<friction>
						<ode>
							<mu>0.1</mu>
							<mu2>0.1</mu2>
						</ode>
					</friction>
					<contact>
						<collide_without_contact>0</collide_without_contact>
					</contact>
				</surface>
			</collision>

			<collision name="whiskeye_head_1_row_mini_2_row_reduced_1.dae_collision">
				<pose>0 0 0 0 0 0</pose>
				<geometry>
					<mesh>
						<uri>model://robot/mesh/lo/whiskeye_head_1_row_mini_2_row_reduced_1.dae</uri>
					</mesh>
				</geometry>
				<surface>
					<friction>
						<ode>
							<mu>0.1</mu>
							<mu2>0.1</mu2>
						</ode>
					</friction>
					<contact>
						<collide_without_contact>0</collide_without_contact>
					</contact>
				</surface>
			</collision>

			<collision name="whiskeye_head_1_pi_compute_1.dae_collision">
				<pose>0 0 0 0 0 0</pose>
				<geometry>
					<mesh>
						<uri>model://robot/mesh/lo/whiskeye_head_1_pi_compute_1.dae</uri>
					</mesh>
				</geometry>
				<surface>
					<friction>
						<ode>
							<mu>0.1</mu>
							<mu2>0.1</mu2>
						</ode>
					</friction>
					<contact>
						<collide_without_contact>0</collide_without_contact>
					</contact>
				</surface>
			</collision>

			<collision name="whiskeye_head_1_eyemount_camholder_reduced_1.dae_collision">
				<pose>0 0 0 0 0 0</pose>
				<geometry>
					<mesh>
						<uri>model://robot/mesh/lo/whiskeye_head_1_eyemount_camholder_reduced_1.dae</uri>
					</mesh>
				</geometry>
				<surface>
					<friction>
						<ode>
							<mu>0.1</mu>
							<mu2>0.1</mu2>
						</ode>
					</friction>
					<contact>
						<collide_without_contact>0</collide_without_contact>
					</contact>
				</surface>
			</collision>

			<collision name="whiskeye_head_1_row_mini_6_row_reduced_1.dae_collision">
				<pose>0 0 0 0 0 0</pose>
				<geometry>
					<mesh>
						<uri>model://robot/mesh/lo/whiskeye_head_1_row_mini_6_row_reduced_1.dae</uri>
					</mesh>
				</geometry>
				<surface>
					<friction>
						<ode>
							<mu>0.1</mu>
							<mu2>0.1</mu2>
						</ode>
					</friction>
					<contact>
						<collide_without_contact>0</collide_without_contact>
					</contact>
				</surface>
			</collision>

			<collision name="whiskeye_head_1_row_mini_1_row_reduced_1.dae_collision">
				<pose>0 0 0 0 0 0</pose>
				<geometry>
					<mesh>
						<uri>model://robot/mesh/lo/whiskeye_head_1_row_mini_1_row_reduced_1.dae</uri>
					</mesh>
				</geometry>
				<surface>
					<friction>
						<ode>
							<mu>0.1</mu>
							<mu2>0.1</mu2>
						</ode>
					</friction>
					<contact>
						<collide_without_contact>0</collide_without_contact>
					</contact>
				</surface>
			</collision>

			<sensor name="cam0" type="camera">
				<pose>0.075 0.07 0.52 0.9 -2.27 -0.79</pose>
				<camera>
					<horizontal_fov>1.57</horizontal_fov>
					<image>
						<width>640</width>
						<height>480</height>
					</image>
					<clip>
						<near>0.001</near>
						<far>200</far>
					</clip>
				</camera>
				<always_on>1</always_on>
				<update_rate>5</update_rate>
				<visualize>false</visualize>
				<topic>/whiskeye/head/cam0/image_raw</topic>
			</sensor>

			<sensor name="cam1" type="camera">
				<pose>0.075 -0.07 0.52 -0.9 -2.27 0.79</pose>
				<camera>
					<horizontal_fov>1.57</horizontal_fov>
					<image>
						<width>640</width>
						<height>480</height>
					</image>
					<clip>
						<near>0.001</near>
						<far>200</far>
					</clip>
				</camera>
				<always_on>1</always_on>
				<update_rate>5</update_rate>
				<visualize>false</visualize>
				<topic>/whiskeye/head/cam1/image_raw</topic>
			</sensor>

			<visual name="datum_1">
				<pose>0.177402 -0.000425 0.647431 0 0 0</pose>
				<geometry>
					<sphere>
						<radius>0.005</radius>
					</sphere>
				</geometry>
				<material>
					<ambient>1 0 0 1</ambient>
					<diffuse>1 0 0 1</diffuse>
					<specular>1 0 0 1</specular>
				</material>
			</visual>

		</link>

		<joint type="revolute" name="head_whisker1_1">
			<pose>0.204628780484 -0.0665908977389 0.579591214657 0 0 0</pose>
			<parent>head</parent>
			<child>whisker1_1</child>
			<axis>
				<xyz>-0.000974449212663 -0.000218293003854 5.2886964113e-05</xyz>
				<limit>
					<lower>-1.0471975511965976</lower>
					<upper>1.0471975511965976</upper>
				</limit>
				<dynamics>
					<friction>0.1</friction>
					<damping>0.1</damping>
				</dynamics>
			</axis>
		</joint>

		<link name="whisker1_1">
			<inertial>
				<pose>0.204628780484 -0.0665908977389 0.579591214657 0 0 0</pose>
				<mass>0.01</mass>
				<inertia>
					<ixx>0.001</ixx>
					<ixy>0</ixy>
					<ixz>0</ixz>
					<iyy>0.001</iyy>
					<iyz>0</iyz>
					<izz>0.001</izz>
				</inertia>
			</inertial>
			<visual name="whiskeye_head_1_row_mini_1_whiskerasm_soc_100mm_1.dae_visual">
				<pose>0 0 0 0 0 0</pose>
				<geometry>
					<mesh>
						<uri>model://robot/mesh/hi/whiskeye_head_1_row_mini_1_whiskerasm_soc_100mm_1.dae</uri>
					</mesh>
				</geometry>
				<material>
					<ambient>0.1 0.1 0.1 1</ambient>
					<diffuse>0.1 0.1 0.1 1</diffuse>
					<specular>0.1 0.1 0.1 1</specular>
				</material>
			</visual>

			<collision name="whiskeye_head_1_row_mini_1_whiskerasm_soc_100mm_1.dae_collision">
				<pose>0 0 0 0 0 0</pose>
				<geometry>
					<mesh>
						<uri>model://robot/mesh/lo/whiskeye_head_1_row_mini_1_whiskerasm_soc_100mm_1.dae</uri>
					</mesh>
				</geometry>
				<surface>
					<friction>
						<ode>
							<mu>0.1</mu>
							<mu2>0.1</mu2>
						</ode>
					</friction>
					<contact>
						<collide_without_contact>1</collide_without_contact>
					</contact>
				</surface>
			</collision>


			<sensor name="whisker1_1_contact" type="contact">
				<contact>
					<collision>whiskeye_head_1_row_mini_1_whiskerasm_soc_100mm_1.dae_collision</collision>
				</contact>
				<always_on>1</always_on>
				<update_rate>50</update_rate>
				<visualize>false</visualize>
			</sensor>

		</link>

		<joint type="revolute" name="head_whisker1_2">
			<pose>0.206240400672 -0.0794981122017 0.567144215107 0 0 0</pose>
			<parent>head</parent>
			<child>whisker1_2</child>
			<axis>
				<xyz>-0.000982769648544 -0.000183988158824 1.76757785084e-05</xyz>
				<limit>
					<lower>-1.0471975511965976</lower>
					<upper>1.0471975511965976</upper>
				</limit>
				<dynamics>
					<friction>0.1</friction>
					<damping>0.1</damping>
				</dynamics>
			</axis>
		</joint>

		<link name="whisker1_2">
			<inertial>
				<pose>0.206240400672 -0.0794981122017 0.567144215107 0 0 0</pose>
				<mass>0.01</mass>
				<inertia>
					<ixx>0.001</ixx>
					<ixy>0</ixy>
					<ixz>0</ixz>
					<iyy>0.001</iyy>
					<iyz>0</iyz>
					<izz>0.001</izz>
				</inertia>
			</inertial>
			<visual name="whiskeye_head_1_row_mini_1_whiskerasm_soc_150mm_1.dae_visual">
				<pose>0 0 0 0 0 0</pose>
				<geometry>
					<mesh>
						<uri>model://robot/mesh/hi/whiskeye_head_1_row_mini_1_whiskerasm_soc_150mm_1.dae</uri>
					</mesh>
				</geometry>
				<material>
					<ambient>0.1 0.1 0.1 1</ambient>
					<diffuse>0.1 0.1 0.1 1</diffuse>
					<specular>0.1 0.1 0.1 1</specular>
				</material>
			</visual>

			<collision name="whiskeye_head_1_row_mini_1_whiskerasm_soc_150mm_1.dae_collision">
				<pose>0 0 0 0 0 0</pose>
				<geometry>
					<mesh>
						<uri>model://robot/mesh/lo/whiskeye_head_1_row_mini_1_whiskerasm_soc_150mm_1.dae</uri>
					</mesh>
				</geometry>
				<surface>
					<friction>
						<ode>
							<mu>0.1</mu>
							<mu2>0.1</mu2>
						</ode>
					</friction>
					<contact>
						<collide_without_contact>1</collide_without_contact>
					</contact>
				</surface>
			</collision>

			<sensor name="whisker1_2_contact" type="contact">
				<contact>
					<collision>whiskeye_head_1_row_mini_1_whiskerasm_soc_150mm_1.dae_collision</collision>
				</contact>
				<always_on>1</always_on>
				<update_rate>50</update_rate>
				<visualize>false</visualize>
			</sensor>

		</link>

		<joint type="revolute" name="head_whisker1_3">
			<pose>0.207575842738 -0.0920694619417 0.554314017296 0 0 0</pose>
			<parent>head</parent>
			<child>whisker1_3</child>
			<axis>
				<xyz>-0.000988658634014 -0.000149137937115 -1.76696867129e-05</xyz>
				<limit>
					<lower>-1.0471975511965976</lower>
					<upper>1.0471975511965976</upper>
				</limit>
				<dynamics>
					<friction>0.1</friction>
					<damping>0.1</damping>
				</dynamics>
			</axis>
		</joint>

		<link name="whisker1_3">
			<inertial>
				<pose>0.207575842738 -0.0920694619417 0.554314017296 0 0 0</pose>
				<mass>0.01</mass>
				<inertia>
					<ixx>0.001</ixx>
					<ixy>0</ixy>
					<ixz>0</ixz>
					<iyy>0.001</iyy>
					<iyz>0</iyz>
					<izz>0.001</izz>
				</inertia>
			</inertial>
			<visual name="whiskeye_head_1_row_mini_1_whiskerasm_soc_220mm_1.dae_visual">
				<pose>0 0 0 0 0 0</pose>
				<geometry>
					<mesh>
						<uri>model://robot/mesh/hi/whiskeye_head_1_row_mini_1_whiskerasm_soc_220mm_1.dae</uri>
					</mesh>
				</geometry>
				<material>
					<ambient>0.1 0.1 0.1 1</ambient>
					<diffuse>0.1 0.1 0.1 1</diffuse>
					<specular>0.1 0.1 0.1 1</specular>
				</material>
			</visual>

			<collision name="whiskeye_head_1_row_mini_1_whiskerasm_soc_220mm_1.dae_collision">
				<pose>0 0 0 0 0 0</pose>
				<geometry>
					<mesh>
						<uri>model://robot/mesh/lo/whiskeye_head_1_row_mini_1_whiskerasm_soc_220mm_1.dae</uri>
					</mesh>
				</geometry>
				<surface>
					<friction>
						<ode>
							<mu>0.1</mu>
							<mu2>0.1</mu2>
						</ode>
					</friction>
					<contact>
						<collide_without_contact>1</collide_without_contact>
					</contact>
				</surface>
			</collision>

			<sensor name="whisker1_3_contact" type="contact">
				<contact>
					<collision>whiskeye_head_1_row_mini_1_whiskerasm_soc_220mm_1.dae_collision</collision>
				</contact>
				<always_on>1</always_on>
				<update_rate>50</update_rate>
				<visualize>false</visualize>
			</sensor>

		</link>

		<joint type="revolute" name="head_whisker1_4">
			<pose>0.208876743913 -0.104273945093 0.541092574596 0 0 0</pose>
			<parent>head</parent>
			<child>whisker1_4</child>
			<axis>
				<xyz>-0.000992071814835 -0.00011400301446 -5.28869750269e-05</xyz>
				<limit>
					<lower>-1.0471975511965976</lower>
					<upper>1.0471975511965976</upper>
				</limit>
				<dynamics>
					<friction>0.1</friction>
					<damping>0.1</damping>
				</dynamics>
			</axis>
		</joint>

		<link name="whisker1_4">
			<inertial>
				<pose>0.208876743913 -0.104273945093 0.541092574596 0 0 0</pose>
				<mass>0.01</mass>
				<inertia>
					<ixx>0.001</ixx>
					<ixy>0</ixy>
					<ixz>0</ixz>
					<iyy>0.001</iyy>
					<iyz>0</iyz>
					<izz>0.001</izz>
				</inertia>
			</inertial>
			<visual name="whiskeye_head_1_row_mini_1_whiskerasm_soc_300mm_1.dae_visual">
				<pose>0 0 0 0 0 0</pose>
				<geometry>
					<mesh>
						<uri>model://robot/mesh/hi/whiskeye_head_1_row_mini_1_whiskerasm_soc_300mm_1.dae</uri>
					</mesh>
				</geometry>
				<material>
					<ambient>0.1 0.1 0.1 1</ambient>
					<diffuse>0.1 0.1 0.1 1</diffuse>
					<specular>0.1 0.1 0.1 1</specular>
				</material>
			</visual>

			<collision name="whiskeye_head_1_row_mini_1_whiskerasm_soc_300mm_1.dae_collision">
				<pose>0 0 0 0 0 0</pose>
				<geometry>
					<mesh>
						<uri>model://robot/mesh/lo/whiskeye_head_1_row_mini_1_whiskerasm_soc_300mm_1.dae</uri>
					</mesh>
				</geometry>
				<surface>
					<friction>
						<ode>
							<mu>0.1</mu>
							<mu2>0.1</mu2>
						</ode>
					</friction>
					<contact>
						<collide_without_contact>1</collide_without_contact>
					</contact>
				</surface>
			</collision>

			<sensor name="whisker1_4_contact" type="contact">
				<contact>
					<collision>whiskeye_head_1_row_mini_1_whiskerasm_soc_300mm_1.dae_collision</collision>
				</contact>
				<always_on>1</always_on>
				<update_rate>50</update_rate>
				<visualize>false</visualize>
			</sensor>

		</link>

		<joint type="revolute" name="head_whisker2_1">
			<pose>0.157603174448 -0.0624267235398 0.589046180248 0 0 0</pose>
			<parent>head</parent>
			<child>whisker2_1</child>
			<axis>
				<xyz>-0.000948052678723 0.000313686643494 5.28869459231e-05</xyz>
				<limit>
					<lower>-1.0471975511965976</lower>
					<upper>1.0471975511965976</upper>
				</limit>
				<dynamics>
					<friction>0.1</friction>
					<damping>0.1</damping>
				</dynamics>
			</axis>
		</joint>

		<link name="whisker2_1">
			<inertial>
				<pose>0.157603174448 -0.0624267235398 0.589046180248 0 0 0</pose>
				<mass>0.01</mass>
				<inertia>
					<ixx>0.001</ixx>
					<ixy>0</ixy>
					<ixz>0</ixz>
					<iyy>0.001</iyy>
					<iyz>0</iyz>
					<izz>0.001</izz>
				</inertia>
			</inertial>
			<visual name="whiskeye_head_1_row_mini_2_whiskerasm_soc_100mm_1.dae_visual">
				<pose>0 0 0 0 0 0</pose>
				<geometry>
					<mesh>
						<uri>model://robot/mesh/hi/whiskeye_head_1_row_mini_2_whiskerasm_soc_100mm_1.dae</uri>
					</mesh>
				</geometry>
				<material>
					<ambient>0.1 0.1 0.1 1</ambient>
					<diffuse>0.1 0.1 0.1 1</diffuse>
					<specular>0.1 0.1 0.1 1</specular>
				</material>
			</visual>

			<collision name="whiskeye_head_1_row_mini_2_whiskerasm_soc_100mm_1.dae_collision">
				<pose>0 0 0 0 0 0</pose>
				<geometry>
					<mesh>
						<uri>model://robot/mesh/lo/whiskeye_head_1_row_mini_2_whiskerasm_soc_100mm_1.dae</uri>
					</mesh>
				</geometry>
				<surface>
					<friction>
						<ode>
							<mu>0.1</mu>
							<mu2>0.1</mu2>
						</ode>
					</friction>
					<contact>
						<collide_without_contact>1</collide_without_contact>
					</contact>
				</surface>
			</collision>

			<sensor name="whisker2_1_contact" type="contact">
				<contact>
					<collision>whiskeye_head_1_row_mini_2_whiskerasm_soc_100mm_1.dae_collision</collision>
				</contact>
				<always_on>1</always_on>
				<update_rate>50</update_rate>
				<visualize>false</visualize>
			</sensor>

		</link>

		<joint type="revolute" name="head_whisker2_2">
			<pose>0.152350410819 -0.0743263810873 0.576599121094 0 0 0</pose>
			<parent>head</parent>
			<child>whisker2_2</child>
			<axis>
				<xyz>-0.000937554286793 0.000347389752278 1.76757694135e-05</xyz>
				<limit>
					<lower>-1.0471975511965976</lower>
					<upper>1.0471975511965976</upper>
				</limit>
				<dynamics>
					<friction>0.1</friction>
					<damping>0.1</damping>
				</dynamics>
			</axis>
		</joint>

		<link name="whisker2_2">
			<inertial>
				<pose>0.152350410819 -0.0743263810873 0.576599121094 0 0 0</pose>
				<mass>0.01</mass>
				<inertia>
					<ixx>0.001</ixx>
					<ixy>0</ixy>
					<ixz>0</ixz>
					<iyy>0.001</iyy>
					<iyz>0</iyz>
					<izz>0.001</izz>
				</inertia>
			</inertial>
			<visual name="whiskeye_head_1_row_mini_2_whiskerasm_soc_150mm_1.dae_visual">
				<pose>0 0 0 0 0 0</pose>
				<geometry>
					<mesh>
						<uri>model://robot/mesh/hi/whiskeye_head_1_row_mini_2_whiskerasm_soc_150mm_1.dae</uri>
					</mesh>
				</geometry>
				<material>
					<ambient>0.1 0.1 0.1 1</ambient>
					<diffuse>0.1 0.1 0.1 1</diffuse>
					<specular>0.1 0.1 0.1 1</specular>
				</material>
			</visual>

			<collision name="whiskeye_head_1_row_mini_2_whiskerasm_soc_150mm_1.dae_collision">
				<pose>0 0 0 0 0 0</pose>
				<geometry>
					<mesh>
						<uri>model://robot/mesh/lo/whiskeye_head_1_row_mini_2_whiskerasm_soc_150mm_1.dae</uri>
					</mesh>
				</geometry>
				<surface>
					<friction>
						<ode>
							<mu>0.1</mu>
							<mu2>0.1</mu2>
						</ode>
					</friction>
					<contact>
						<collide_without_contact>1</collide_without_contact>
					</contact>
				</surface>
			</collision>

			<sensor name="whisker2_2_contact" type="contact">
				<contact>
					<collision>whiskeye_head_1_row_mini_2_whiskerasm_soc_150mm_1.dae_collision</collision>
				</contact>
				<always_on>1</always_on>
				<update_rate>50</update_rate>
				<visualize>false</visualize>
			</sensor>

		</link>

		<joint type="revolute" name="head_whisker2_3">
			<pose>0.147033423185 -0.0857959911227 0.563769042492 0 0 0</pose>
			<parent>head</parent>
			<child>whisker2_3</child>
			<axis>
				<xyz>-0.000924690277316 0.000380309938919 -1.76758112502e-05</xyz>
				<limit>
					<lower>-1.0471975511965976</lower>
					<upper>1.0471975511965976</upper>
				</limit>
				<dynamics>
					<friction>0.1</friction>
					<damping>0.1</damping>
				</dynamics>
			</axis>
		</joint>

		<link name="whisker2_3">
			<inertial>
				<pose>0.147033423185 -0.0857959911227 0.563769042492 0 0 0</pose>
				<mass>0.01</mass>
				<inertia>
					<ixx>0.001</ixx>
					<ixy>0</ixy>
					<ixz>0</ixz>
					<iyy>0.001</iyy>
					<iyz>0</iyz>
					<izz>0.001</izz>
				</inertia>
			</inertial>
			<visual name="whiskeye_head_1_row_mini_2_whiskerasm_soc_220mm_1.dae_visual">
				<pose>0 0 0 0 0 0</pose>
				<geometry>
					<mesh>
						<uri>model://robot/mesh/hi/whiskeye_head_1_row_mini_2_whiskerasm_soc_220mm_1.dae</uri>
					</mesh>
				</geometry>
				<material>
					<ambient>0.1 0.1 0.1 1</ambient>
					<diffuse>0.1 0.1 0.1 1</diffuse>
					<specular>0.1 0.1 0.1 1</specular>
				</material>
			</visual>

			<collision name="whiskeye_head_1_row_mini_2_whiskerasm_soc_220mm_1.dae_collision">
				<pose>0 0 0 0 0 0</pose>
				<geometry>
					<mesh>
						<uri>model://robot/mesh/lo/whiskeye_head_1_row_mini_2_whiskerasm_soc_220mm_1.dae</uri>
					</mesh>
				</geometry>
				<surface>
					<friction>
						<ode>
							<mu>0.1</mu>
							<mu2>0.1</mu2>
						</ode>
					</friction>
					<contact>
						<collide_without_contact>1</collide_without_contact>
					</contact>
				</surface>
			</collision>

			<sensor name="whisker2_3_contact" type="contact">
				<contact>
					<collision>whiskeye_head_1_row_mini_2_whiskerasm_soc_220mm_1.dae_collision</collision>
				</contact>
				<always_on>1</always_on>
				<update_rate>50</update_rate>
				<visualize>false</visualize>
			</sensor>

		</link>

		<joint type="revolute" name="head_whisker2_4">
			<pose>0.141875401139 -0.0969331711531 0.550547420979 0 0 0</pose>
			<parent>head</parent>
			<child>whisker2_4</child>
			<axis>
				<xyz>-0.000909556751139 0.00041220174171 -5.28808668605e-05</xyz>
				<limit>
					<lower>-1.0471975511965976</lower>
					<upper>1.0471975511965976</upper>
				</limit>
				<dynamics>
					<friction>0.1</friction>
					<damping>0.1</damping>
				</dynamics>
			</axis>
		</joint>

		<link name="whisker2_4">
			<inertial>
				<pose>0.141875401139 -0.0969331711531 0.550547420979 0 0 0</pose>
				<mass>0.01</mass>
				<inertia>
					<ixx>0.001</ixx>
					<ixy>0</ixy>
					<ixz>0</ixz>
					<iyy>0.001</iyy>
					<iyz>0</iyz>
					<izz>0.001</izz>
				</inertia>
			</inertial>
			<visual name="whiskeye_head_1_row_mini_2_whiskerasm_soc_300mm_1.dae_visual">
				<pose>0 0 0 0 0 0</pose>
				<geometry>
					<mesh>
						<uri>model://robot/mesh/hi/whiskeye_head_1_row_mini_2_whiskerasm_soc_300mm_1.dae</uri>
					</mesh>
				</geometry>
				<material>
					<ambient>0.1 0.1 0.1 1</ambient>
					<diffuse>0.1 0.1 0.1 1</diffuse>
					<specular>0.1 0.1 0.1 1</specular>
				</material>
			</visual>

			<collision name="whiskeye_head_1_row_mini_2_whiskerasm_soc_300mm_1.dae_collision">
				<pose>0 0 0 0 0 0</pose>
				<geometry>
					<mesh>
						<uri>model://robot/mesh/lo/whiskeye_head_1_row_mini_2_whiskerasm_soc_300mm_1.dae</uri>
					</mesh>
				</geometry>
				<surface>
					<friction>
						<ode>
							<mu>0.1</mu>
							<mu2>0.1</mu2>
						</ode>
					</friction>
					<contact>
						<collide_without_contact>1</collide_without_contact>
					</contact>
				</surface>
			</collision>


			<sensor name="whisker2_4_contact" type="contact">
				<contact>
					<collision>whiskeye_head_1_row_mini_2_whiskerasm_soc_300mm_1.dae_collision</collision>
				</contact>
				<always_on>1</always_on>
				<update_rate>50</update_rate>
				<visualize>false</visualize>
			</sensor>

		</link>

		<joint type="revolute" name="head_whisker3_1">
			<pose>0.120149634778 -0.0271606687456 0.597895681858 0 0 0</pose>
			<parent>head</parent>
			<child>whisker3_1</child>
			<axis>
				<xyz>-0.000436542497482 0.000898128258996 5.28808559466e-05</xyz>
				<limit>
					<lower>-1.0471975511965976</lower>
					<upper>1.0471975511965976</upper>
				</limit>
				<dynamics>
					<friction>0.1</friction>
					<damping>0.1</damping>
				</dynamics>
			</axis>
		</joint>

		<link name="whisker3_1">
			<inertial>
				<pose>0.120149634778 -0.0271606687456 0.597895681858 0 0 0</pose>
				<mass>0.01</mass>
				<inertia>
					<ixx>0.001</ixx>
					<ixy>0</ixy>
					<ixz>0</ixz>
					<iyy>0.001</iyy>
					<iyz>0</iyz>
					<izz>0.001</izz>
				</inertia>
			</inertial>
			<visual name="whiskeye_head_1_row_mini_3_whiskerasm_soc_100mm_1.dae_visual">
				<pose>0 0 0 0 0 0</pose>
				<geometry>
					<mesh>
						<uri>model://robot/mesh/hi/whiskeye_head_1_row_mini_3_whiskerasm_soc_100mm_1.dae</uri>
					</mesh>
				</geometry>
				<material>
					<ambient>0.1 0.1 0.1 1</ambient>
					<diffuse>0.1 0.1 0.1 1</diffuse>
					<specular>0.1 0.1 0.1 1</specular>
				</material>
			</visual>

			<collision name="whiskeye_head_1_row_mini_3_whiskerasm_soc_100mm_1.dae_collision">
				<pose>0 0 0 0 0 0</pose>
				<geometry>
					<mesh>
						<uri>model://robot/mesh/lo/whiskeye_head_1_row_mini_3_whiskerasm_soc_100mm_1.dae</uri>
					</mesh>
				</geometry>
				<surface>
					<friction>
						<ode>
							<mu>0.1</mu>
							<mu2>0.1</mu2>
						</ode>
					</friction>
					<contact>
						<collide_without_contact>1</collide_without_contact>
					</contact>
				</surface>
			</collision>

			<sensor name="whisker3_1_contact" type="contact">
				<contact>
					<collision>whiskeye_head_1_row_mini_3_whiskerasm_soc_100mm_1.dae_collision</collision>
				</contact>
				<always_on>1</always_on>
				<update_rate>50</update_rate>
				<visualize>false</visualize>
			</sensor>

		</link>

		<joint type="revolute" name="head_whisker3_2">
			<pose>0.107959009707 -0.0316974185407 0.585448622704 0 0 0</pose>
			<parent>head</parent>
			<child>whisker3_2</child>
			<axis>
				<xyz>-0.00040506903315 0.000914115458727 1.76696812559e-05</xyz>
				<limit>
					<lower>-1.0471975511965976</lower>
					<upper>1.0471975511965976</upper>
				</limit>
				<dynamics>
					<friction>0.1</friction>
					<damping>0.1</damping>
				</dynamics>
			</axis>
		</joint>

		<link name="whisker3_2">
			<inertial>
				<pose>0.107959009707 -0.0316974185407 0.585448622704 0 0 0</pose>
				<mass>0.01</mass>
				<inertia>
					<ixx>0.001</ixx>
					<ixy>0</ixy>
					<ixz>0</ixz>
					<iyy>0.001</iyy>
					<iyz>0</iyz>
					<izz>0.001</izz>
				</inertia>
			</inertial>
			<visual name="whiskeye_head_1_row_mini_3_whiskerasm_soc_150mm_1.dae_visual">
				<pose>0 0 0 0 0 0</pose>
				<geometry>
					<mesh>
						<uri>model://robot/mesh/hi/whiskeye_head_1_row_mini_3_whiskerasm_soc_150mm_1.dae</uri>
					</mesh>
				</geometry>
				<material>
					<ambient>0.1 0.1 0.1 1</ambient>
					<diffuse>0.1 0.1 0.1 1</diffuse>
					<specular>0.1 0.1 0.1 1</specular>
				</material>
			</visual>

			<collision name="whiskeye_head_1_row_mini_3_whiskerasm_soc_150mm_1.dae_collision">
				<pose>0 0 0 0 0 0</pose>
				<geometry>
					<mesh>
						<uri>model://robot/mesh/lo/whiskeye_head_1_row_mini_3_whiskerasm_soc_150mm_1.dae</uri>
					</mesh>
				</geometry>
				<surface>
					<friction>
						<ode>
							<mu>0.1</mu>
							<mu2>0.1</mu2>
						</ode>
					</friction>
					<contact>
						<collide_without_contact>1</collide_without_contact>
					</contact>
				</surface>
			</collision>

			<sensor name="whisker3_2_contact" type="contact">
				<contact>
					<collision>whiskeye_head_1_row_mini_3_whiskerasm_soc_150mm_1.dae_collision</collision>
				</contact>
				<always_on>1</always_on>
				<update_rate>50</update_rate>
				<visualize>false</visualize>
			</sensor>

		</link>

		<joint type="revolute" name="head_whisker3_3">
			<pose>0.0960317254066 -0.0358881764114 0.572618424892 0 0 0</pose>
			<parent>head</parent>
			<child>whisker3_3</child>
			<axis>
				<xyz>-0.000372506881831 0.000927861256059 -1.76696867129e-05</xyz>
				<limit>
					<lower>-1.0471975511965976</lower>
					<upper>1.0471975511965976</upper>
				</limit>
				<dynamics>
					<friction>0.1</friction>
					<damping>0.1</damping>
				</dynamics>
			</axis>
		</joint>

		<link name="whisker3_3">
			<inertial>
				<pose>0.0960317254066 -0.0358881764114 0.572618424892 0 0 0</pose>
				<mass>0.01</mass>
				<inertia>
					<ixx>0.001</ixx>
					<ixy>0</ixy>
					<ixz>0</ixz>
					<iyy>0.001</iyy>
					<iyz>0</iyz>
					<izz>0.001</izz>
				</inertia>
			</inertial>
			<visual name="whiskeye_head_1_row_mini_3_whiskerasm_soc_220mm_1.dae_visual">
				<pose>0 0 0 0 0 0</pose>
				<geometry>
					<mesh>
						<uri>model://robot/mesh/hi/whiskeye_head_1_row_mini_3_whiskerasm_soc_220mm_1.dae</uri>
					</mesh>
				</geometry>
				<material>
					<ambient>0.1 0.1 0.1 1</ambient>
					<diffuse>0.1 0.1 0.1 1</diffuse>
					<specular>0.1 0.1 0.1 1</specular>
				</material>
			</visual>


			<collision name="whiskeye_head_1_row_mini_3_whiskerasm_soc_220mm_1.dae_collision">
				<pose>0 0 0 0 0 0</pose>
				<geometry>
					<mesh>
						<uri>model://robot/mesh/lo/whiskeye_head_1_row_mini_3_whiskerasm_soc_220mm_1.dae</uri>
					</mesh>
				</geometry>
				<surface>
					<friction>
						<ode>
							<mu>0.1</mu>
							<mu2>0.1</mu2>
						</ode>
					</friction>
					<contact>
						<collide_without_contact>1</collide_without_contact>
					</contact>
				</surface>
			</collision>

			<sensor name="whisker3_3_contact" type="contact">
				<contact>
					<collision>whiskeye_head_1_row_mini_3_whiskerasm_soc_220mm_1.dae_collision</collision>
				</contact>
				<always_on>1</always_on>
				<update_rate>50</update_rate>
				<visualize>false</visualize>
			</sensor>

		</link>

		<joint type="revolute" name="head_whisker3_4">
			<pose>0.0844535380602 -0.0399609543383 0.559396862984 0 0 0</pose>
			<parent>head</parent>
			<child>whisker3_4</child>
			<axis>
				<xyz>-0.000339099060511 0.000939263030887 -5.2886956837e-05</xyz>
				<limit>
					<lower>-1.0471975511965976</lower>
					<upper>1.0471975511965976</upper>
				</limit>
				<dynamics>
					<friction>0.1</friction>
					<damping>0.1</damping>
				</dynamics>
			</axis>
		</joint>

		<link name="whisker3_4">
			<inertial>
				<pose>0.0844535380602 -0.0399609543383 0.559396862984 0 0 0</pose>
				<mass>0.01</mass>
				<inertia>
					<ixx>0.001</ixx>
					<ixy>0</ixy>
					<ixz>0</ixz>
					<iyy>0.001</iyy>
					<iyz>0</iyz>
					<izz>0.001</izz>
				</inertia>
			</inertial>
			<visual name="whiskeye_head_1_row_mini_3_whiskerasm_soc_300mm_1.dae_visual">
				<pose>0 0 0 0 0 0</pose>
				<geometry>
					<mesh>
						<uri>model://robot/mesh/hi/whiskeye_head_1_row_mini_3_whiskerasm_soc_300mm_1.dae</uri>
					</mesh>
				</geometry>
				<material>
					<ambient>0.1 0.1 0.1 1</ambient>
					<diffuse>0.1 0.1 0.1 1</diffuse>
					<specular>0.1 0.1 0.1 1</specular>
				</material>
			</visual>

			<collision name="whiskeye_head_1_row_mini_3_whiskerasm_soc_300mm_1.dae_collision">
				<pose>0 0 0 0 0 0</pose>
				<geometry>
					<mesh>
						<uri>model://robot/mesh/lo/whiskeye_head_1_row_mini_3_whiskerasm_soc_300mm_1.dae</uri>
					</mesh>
				</geometry>
				<surface>
					<friction>
						<ode>
							<mu>0.1</mu>
							<mu2>0.1</mu2>
						</ode>
					</friction>
					<contact>
						<collide_without_contact>1</collide_without_contact>
					</contact>
				</surface>
			</collision>

			<sensor name="whisker3_4_contact" type="contact">
				<contact>
					<collision>whiskeye_head_1_row_mini_3_whiskerasm_soc_300mm_1.dae_collision</collision>
				</contact>
				<always_on>1</always_on>
				<update_rate>50</update_rate>
				<visualize>false</visualize>
			</sensor>

		</link>

		<joint type="revolute" name="head_whisker4_1">
			<pose>0.119293801486 0.0242838524282 0.597895681858 0 0 0</pose>
			<parent>head</parent>
			<child>whisker4_1</child>
			<axis>
				<xyz>0.000339099846315 0.000939263030887 5.28808523086e-05</xyz>
				<limit>
					<lower>-1.0471975511965976</lower>
					<upper>1.0471975511965976</upper>
				</limit>
				<dynamics>
					<friction>0.1</friction>
					<damping>0.1</damping>
				</dynamics>
			</axis>
		</joint>

		<link name="whisker4_1">
			<inertial>
				<pose>0.119293801486 0.0242838524282 0.597895681858 0 0 0</pose>
				<mass>0.01</mass>
				<inertia>
					<ixx>0.001</ixx>
					<ixy>0</ixy>
					<ixz>0</ixz>
					<iyy>0.001</iyy>
					<iyz>0</iyz>
					<izz>0.001</izz>
				</inertia>
			</inertial>
			<visual name="whiskeye_head_1_row_mini_4_whiskerasm_soc_100mm_1.dae_visual">
				<pose>0 0 0 0 0 0</pose>
				<geometry>
					<mesh>
						<uri>model://robot/mesh/hi/whiskeye_head_1_row_mini_4_whiskerasm_soc_100mm_1.dae</uri>
					</mesh>
				</geometry>
				<material>
					<ambient>0.1 0.1 0.1 1</ambient>
					<diffuse>0.1 0.1 0.1 1</diffuse>
					<specular>0.1 0.1 0.1 1</specular>
				</material>
			</visual>

			<collision name="whiskeye_head_1_row_mini_4_whiskerasm_soc_100mm_1.dae_collision">
				<pose>0 0 0 0 0 0</pose>
				<geometry>
					<mesh>
						<uri>model://robot/mesh/lo/whiskeye_head_1_row_mini_4_whiskerasm_soc_100mm_1.dae</uri>
					</mesh>
				</geometry>
				<surface>
					<friction>
						<ode>
							<mu>0.1</mu>
							<mu2>0.1</mu2>
						</ode>
					</friction>
					<contact>
						<collide_without_contact>1</collide_without_contact>
					</contact>
				</surface>
			</collision>

			<sensor name="whisker4_1_contact" type="contact">
				<contact>
					<collision>whiskeye_head_1_row_mini_4_whiskerasm_soc_100mm_1.dae_collision</collision>
				</contact>
				<always_on>1</always_on>
				<update_rate>50</update_rate>
				<visualize>false</visualize>
			</sensor>

		</link>

		<joint type="revolute" name="head_whisker4_2">
			<pose>0.107539892197 0.0298551078886 0.585448622704 0 0 0</pose>
			<parent>head</parent>
			<child>whisker4_2</child>
			<axis>
				<xyz>0.000372506823624 0.000927861256059 1.76696830749e-05</xyz>
				<limit>
					<lower>-1.0471975511965976</lower>
					<upper>1.0471975511965976</upper>
				</limit>
				<dynamics>
					<friction>0.1</friction>
					<damping>0.1</damping>
				</dynamics>
			</axis>
		</joint>

		<link name="whisker4_2">
			<inertial>
				<pose>0.107539892197 0.0298551078886 0.585448622704 0 0 0</pose>
				<mass>0.01</mass>
				<inertia>
					<ixx>0.001</ixx>
					<ixy>0</ixy>
					<ixz>0</ixz>
					<iyy>0.001</iyy>
					<iyz>0</iyz>
					<izz>0.001</izz>
				</inertia>
			</inertial>
			<visual name="whiskeye_head_1_row_mini_4_whiskerasm_soc_150mm_1.dae_visual">
				<pose>0 0 0 0 0 0</pose>
				<geometry>
					<mesh>
						<uri>model://robot/mesh/hi/whiskeye_head_1_row_mini_4_whiskerasm_soc_150mm_1.dae</uri>
					</mesh>
				</geometry>
				<material>
					<ambient>0.1 0.1 0.1 1</ambient>
					<diffuse>0.1 0.1 0.1 1</diffuse>
					<specular>0.1 0.1 0.1 1</specular>
				</material>
			</visual>

			<collision name="whiskeye_head_1_row_mini_4_whiskerasm_soc_150mm_1.dae_collision">
				<pose>0 0 0 0 0 0</pose>
				<geometry>
					<mesh>
						<uri>model://robot/mesh/lo/whiskeye_head_1_row_mini_4_whiskerasm_soc_150mm_1.dae</uri>
					</mesh>
				</geometry>
				<surface>
					<friction>
						<ode>
							<mu>0.1</mu>
							<mu2>0.1</mu2>
						</ode>
					</friction>
					<contact>
						<collide_without_contact>1</collide_without_contact>
					</contact>
				</surface>
			</collision>

			<sensor name="whisker4_2_contact" type="contact">
				<contact>
					<collision>whiskeye_head_1_row_mini_4_whiskerasm_soc_150mm_1.dae_collision</collision>
				</contact>
				<always_on>1</always_on>
				<update_rate>50</update_rate>
				<visualize>false</visualize>
			</sensor>

		</link>

		<joint type="revolute" name="head_whisker4_3">
			<pose>0.0962175950408 0.0354789718986 0.572618424892 0 0 0</pose>
			<parent>head</parent>
			<child>whisker4_3</child>
			<axis>
				<xyz>0.000405068451073 0.000914115691558 -1.76696885319e-05</xyz>
				<limit>
					<lower>-1.0471975511965976</lower>
					<upper>1.0471975511965976</upper>
				</limit>
				<dynamics>
					<friction>0.1</friction>
					<damping>0.1</damping>
				</dynamics>
			</axis>
		</joint>

		<link name="whisker4_3">
			<inertial>
				<pose>0.0962175950408 0.0354789718986 0.572618424892 0 0 0</pose>
				<mass>0.01</mass>
				<inertia>
					<ixx>0.001</ixx>
					<ixy>0</ixy>
					<ixz>0</ixz>
					<iyy>0.001</iyy>
					<iyz>0</iyz>
					<izz>0.001</izz>
				</inertia>
			</inertial>
			<visual name="whiskeye_head_1_row_mini_4_whiskerasm_soc_220mm_1.dae_visual">
				<pose>0 0 0 0 0 0</pose>
				<geometry>
					<mesh>
						<uri>model://robot/mesh/hi/whiskeye_head_1_row_mini_4_whiskerasm_soc_220mm_1.dae</uri>
					</mesh>
				</geometry>
				<material>
					<ambient>0.1 0.1 0.1 1</ambient>
					<diffuse>0.1 0.1 0.1 1</diffuse>
					<specular>0.1 0.1 0.1 1</specular>
				</material>
			</visual>

			<collision name="whiskeye_head_1_row_mini_4_whiskerasm_soc_220mm_1.dae_collision">
				<pose>0 0 0 0 0 0</pose>
				<geometry>
					<mesh>
						<uri>model://robot/mesh/lo/whiskeye_head_1_row_mini_4_whiskerasm_soc_220mm_1.dae</uri>
					</mesh>
				</geometry>
				<surface>
					<friction>
						<ode>
							<mu>0.1</mu>
							<mu2>0.1</mu2>
						</ode>
					</friction>
					<contact>
						<collide_without_contact>1</collide_without_contact>
					</contact>
				</surface>
			</collision>

			<sensor name="whisker4_3_contact" type="contact">
				<contact>
					<collision>whiskeye_head_1_row_mini_4_whiskerasm_soc_220mm_1.dae_collision</collision>
				</contact>
				<always_on>1</always_on>
				<update_rate>50</update_rate>
				<visualize>false</visualize>
			</sensor>

		</link>

		<joint type="revolute" name="head_whisker4_4">
			<pose>0.0852233171463 0.0409349873662 0.559396862984 0 0 0</pose>
			<parent>head</parent>
			<child>whisker4_4</child>
			<axis>
				<xyz>0.000436541624367 0.000898128317203 -5.28869495611e-05</xyz>
				<limit>
					<lower>-1.0471975511965976</lower>
					<upper>1.0471975511965976</upper>
				</limit>
				<dynamics>
					<friction>0.1</friction>
					<damping>0.1</damping>
				</dynamics>
			</axis>
		</joint>

		<link name="whisker4_4">
			<inertial>
				<pose>0.0852233171463 0.0409349873662 0.559396862984 0 0 0</pose>
				<mass>0.01</mass>
				<inertia>
					<ixx>0.001</ixx>
					<ixy>0</ixy>
					<ixz>0</ixz>
					<iyy>0.001</iyy>
					<iyz>0</iyz>
					<izz>0.001</izz>
				</inertia>
			</inertial>
			<visual name="whiskeye_head_1_row_mini_4_whiskerasm_soc_300mm_1.dae_visual">
				<pose>0 0 0 0 0 0</pose>
				<geometry>
					<mesh>
						<uri>model://robot/mesh/hi/whiskeye_head_1_row_mini_4_whiskerasm_soc_300mm_1.dae</uri>
					</mesh>
				</geometry>
				<material>
					<ambient>0.1 0.1 0.1 1</ambient>
					<diffuse>0.1 0.1 0.1 1</diffuse>
					<specular>0.1 0.1 0.1 1</specular>
				</material>
			</visual>

			<collision name="whiskeye_head_1_row_mini_4_whiskerasm_soc_300mm_1.dae_collision">
				<pose>0 0 0 0 0 0</pose>
				<geometry>
					<mesh>
						<uri>model://robot/mesh/lo/whiskeye_head_1_row_mini_4_whiskerasm_soc_300mm_1.dae</uri>
					</mesh>
				</geometry>
				<surface>
					<friction>
						<ode>
							<mu>0.1</mu>
							<mu2>0.1</mu2>
						</ode>
					</friction>
					<contact>
						<collide_without_contact>1</collide_without_contact>
					</contact>
				</surface>
			</collision>

			<sensor name="whisker4_4_contact" type="contact">
				<contact>
					<collision>whiskeye_head_1_row_mini_4_whiskerasm_soc_300mm_1.dae_collision</collision>
				</contact>
				<always_on>1</always_on>
				<update_rate>50</update_rate>
				<visualize>false</visualize>
			</sensor>

		</link>

		<joint type="revolute" name="head_whisker5_1">
			<pose>0.155553504825 0.0607763193548 0.589046180248 0 0 0</pose>
			<parent>head</parent>
			<child>whisker5_1</child>
			<axis>
				<xyz>0.000909556634724 0.000412201334257 5.2886964113e-05</xyz>
				<limit>
					<lower>-1.0471975511965976</lower>
					<upper>1.0471975511965976</upper>
				</limit>
				<dynamics>
					<friction>0.1</friction>
					<damping>0.1</damping>
				</dynamics>
			</axis>
		</joint>

		<link name="whisker5_1">
			<inertial>
				<pose>0.155553504825 0.0607763193548 0.589046180248 0 0 0</pose>
				<mass>0.01</mass>
				<inertia>
					<ixx>0.001</ixx>
					<ixy>0</ixy>
					<ixz>0</ixz>
					<iyy>0.001</iyy>
					<iyz>0</iyz>
					<izz>0.001</izz>
				</inertia>
			</inertial>
			<visual name="whiskeye_head_1_row_mini_5_whiskerasm_soc_100mm_1.dae_visual">
				<pose>0 0 0 0 0 0</pose>
				<geometry>
					<mesh>
						<uri>model://robot/mesh/hi/whiskeye_head_1_row_mini_5_whiskerasm_soc_100mm_1.dae</uri>
					</mesh>
				</geometry>
				<material>
					<ambient>0.1 0.1 0.1 1</ambient>
					<diffuse>0.1 0.1 0.1 1</diffuse>
					<specular>0.1 0.1 0.1 1</specular>
				</material>
			</visual>

			<collision name="whiskeye_head_1_row_mini_5_whiskerasm_soc_100mm_1.dae_collision">
				<pose>0 0 0 0 0 0</pose>
				<geometry>
					<mesh>
						<uri>model://robot/mesh/lo/whiskeye_head_1_row_mini_5_whiskerasm_soc_100mm_1.dae</uri>
					</mesh>
				</geometry>
				<surface>
					<friction>
						<ode>
							<mu>0.1</mu>
							<mu2>0.1</mu2>
						</ode>
					</friction>
					<contact>
						<collide_without_contact>1</collide_without_contact>
					</contact>
				</surface>
			</collision>

			<sensor name="whisker5_1_contact" type="contact">
				<contact>
					<collision>whiskeye_head_1_row_mini_5_whiskerasm_soc_100mm_1.dae_collision</collision>
				</contact>
				<always_on>1</always_on>
				<update_rate>50</update_rate>
				<visualize>false</visualize>
			</sensor>

		</link>

		<joint type="revolute" name="head_whisker5_2">
			<pose>0.151346638799 0.0730846747756 0.576599121094 0 0 0</pose>
			<parent>head</parent>
			<child>whisker5_2</child>
			<axis>
				<xyz>0.000924690451939 0.000380309385946 1.76757857844e-05</xyz>
				<limit>
					<lower>-1.0471975511965976</lower>
					<upper>1.0471975511965976</upper>
				</limit>
				<dynamics>
					<friction>0.1</friction>
					<damping>0.1</damping>
				</dynamics>
			</axis>
		</joint>

		<link name="whisker5_2">
			<inertial>
				<pose>0.151346638799 0.0730846747756 0.576599121094 0 0 0</pose>
				<mass>0.01</mass>
				<inertia>
					<ixx>0.001</ixx>
					<ixy>0</ixy>
					<ixz>0</ixz>
					<iyy>0.001</iyy>
					<iyz>0</iyz>
					<izz>0.001</izz>
				</inertia>
			</inertial>
			<visual name="whiskeye_head_1_row_mini_5_whiskerasm_soc_150mm_1.dae_visual">
				<pose>0 0 0 0 0 0</pose>
				<geometry>
					<mesh>
						<uri>model://robot/mesh/hi/whiskeye_head_1_row_mini_5_whiskerasm_soc_150mm_1.dae</uri>
					</mesh>
				</geometry>
				<material>
					<ambient>0.1 0.1 0.1 1</ambient>
					<diffuse>0.1 0.1 0.1 1</diffuse>
					<specular>0.1 0.1 0.1 1</specular>
				</material>
			</visual>

			<collision name="whiskeye_head_1_row_mini_5_whiskerasm_soc_150mm_1.dae_collision">
				<pose>0 0 0 0 0 0</pose>
				<geometry>
					<mesh>
						<uri>model://robot/mesh/lo/whiskeye_head_1_row_mini_5_whiskerasm_soc_150mm_1.dae</uri>
					</mesh>
				</geometry>
				<surface>
					<friction>
						<ode>
							<mu>0.1</mu>
							<mu2>0.1</mu2>
						</ode>
					</friction>
					<contact>
						<collide_without_contact>1</collide_without_contact>
					</contact>
				</surface>
			</collision>

			<sensor name="whisker5_2_contact" type="contact">
				<contact>
					<collision>whiskeye_head_1_row_mini_5_whiskerasm_soc_150mm_1.dae_collision</collision>
				</contact>
				<always_on>1</always_on>
				<update_rate>50</update_rate>
				<visualize>false</visualize>
			</sensor>

		</link>

		<joint type="revolute" name="head_whisker5_3">
			<pose>0.147478550673 0.0851204544306 0.563769042492 0 0 0</pose>
			<parent>head</parent>
			<child>whisker5_3</child>
			<axis>
				<xyz>0.000937554519624 0.000347389053786 -1.76757730515e-05</xyz>
				<limit>
					<lower>-1.0471975511965976</lower>
					<upper>1.0471975511965976</upper>
				</limit>
				<dynamics>
					<friction>0.1</friction>
					<damping>0.1</damping>
				</dynamics>
			</axis>
		</joint>

		<link name="whisker5_3">
			<inertial>
				<pose>0.147478550673 0.0851204544306 0.563769042492 0 0 0</pose>
				<mass>0.01</mass>
				<inertia>
					<ixx>0.001</ixx>
					<ixy>0</ixy>
					<ixz>0</ixz>
					<iyy>0.001</iyy>
					<iyz>0</iyz>
					<izz>0.001</izz>
				</inertia>
			</inertial>
			<visual name="whiskeye_head_1_row_mini_5_whiskerasm_soc_220mm_1.dae_visual">
				<pose>0 0 0 0 0 0</pose>
				<geometry>
					<mesh>
						<uri>model://robot/mesh/hi/whiskeye_head_1_row_mini_5_whiskerasm_soc_220mm_1.dae</uri>
					</mesh>
				</geometry>
				<material>
					<ambient>0.1 0.1 0.1 1</ambient>
					<diffuse>0.1 0.1 0.1 1</diffuse>
					<specular>0.1 0.1 0.1 1</specular>
				</material>
			</visual>

			<collision name="whiskeye_head_1_row_mini_5_whiskerasm_soc_220mm_1.dae_collision">
				<pose>0 0 0 0 0 0</pose>
				<geometry>
					<mesh>
						<uri>model://robot/mesh/lo/whiskeye_head_1_row_mini_5_whiskerasm_soc_220mm_1.dae</uri>
					</mesh>
				</geometry>
				<surface>
					<friction>
						<ode>
							<mu>0.1</mu>
							<mu2>0.1</mu2>
						</ode>
					</friction>
					<contact>
						<collide_without_contact>1</collide_without_contact>
					</contact>
				</surface>
			</collision>

			<sensor name="whisker5_3_contact" type="contact">
				<contact>
					<collision>whiskeye_head_1_row_mini_5_whiskerasm_soc_220mm_1.dae_collision</collision>
				</contact>
				<always_on>1</always_on>
				<update_rate>50</update_rate>
				<visualize>false</visualize>
			</sensor>

		</link>

		<joint type="revolute" name="head_whisker5_4">
			<pose>0.143718972802 0.0968041047454 0.550547420979 0 0 0</pose>
			<parent>head</parent>
			<child>whisker5_4</child>
			<axis>
				<xyz>0.000948052853346 0.000313687109156 -5.28808523086e-05</xyz>
				<limit>
					<lower>-1.0471975511965976</lower>
					<upper>1.0471975511965976</upper>
				</limit>
				<dynamics>
					<friction>0.1</friction>
					<damping>0.1</damping>
				</dynamics>
			</axis>
		</joint>

		<link name="whisker5_4">
			<inertial>
				<pose>0.143718972802 0.0968041047454 0.550547420979 0 0 0</pose>
				<mass>0.01</mass>
				<inertia>
					<ixx>0.001</ixx>
					<ixy>0</ixy>
					<ixz>0</ixz>
					<iyy>0.001</iyy>
					<iyz>0</iyz>
					<izz>0.001</izz>
				</inertia>
			</inertial>
			<visual name="whiskeye_head_1_row_mini_5_whiskerasm_soc_300mm_1.dae_visual">
				<pose>0 0 0 0 0 0</pose>
				<geometry>
					<mesh>
						<uri>model://robot/mesh/hi/whiskeye_head_1_row_mini_5_whiskerasm_soc_300mm_1.dae</uri>
					</mesh>
				</geometry>
				<material>
					<ambient>0.1 0.1 0.1 1</ambient>
					<diffuse>0.1 0.1 0.1 1</diffuse>
					<specular>0.1 0.1 0.1 1</specular>
				</material>
			</visual>

			<collision name="whiskeye_head_1_row_mini_5_whiskerasm_soc_300mm_1.dae_collision">
				<pose>0 0 0 0 0 0</pose>
				<geometry>
					<mesh>
						<uri>model://robot/mesh/lo/whiskeye_head_1_row_mini_5_whiskerasm_soc_300mm_1.dae</uri>
					</mesh>
				</geometry>
				<surface>
					<friction>
						<ode>
							<mu>0.1</mu>
							<mu2>0.1</mu2>
						</ode>
					</friction>
					<contact>
						<collide_without_contact>1</collide_without_contact>
					</contact>
				</surface>
			</collision>

			<sensor name="whisker5_4_contact" type="contact">
				<contact>
					<collision>whiskeye_head_1_row_mini_5_whiskerasm_soc_300mm_1.dae_collision</collision>
				</contact>
				<always_on>1</always_on>
				<update_rate>50</update_rate>
				<visualize>false</visualize>
			</sensor>

		</link>

		<joint type="revolute" name="head_whisker6_1">
			<pose>0.202305734158 0.0660145506263 0.579688489437 0 0 0</pose>
			<parent>head</parent>
			<child>whisker6_1</child>
			<axis>
				<xyz>0.000991233275272 -0.000121080709505 5.28808304807e-05</xyz>
				<limit>
					<lower>-1.0471975511965976</lower>
					<upper>1.0471975511965976</upper>
				</limit>
				<dynamics>
					<friction>0.1</friction>
					<damping>0.1</damping>
				</dynamics>
			</axis>
		</joint>

		<link name="whisker6_1">
			<inertial>
				<pose>0.202305734158 0.0660145506263 0.579688489437 0 0 0</pose>
				<mass>0.01</mass>
				<inertia>
					<ixx>0.001</ixx>
					<ixy>0</ixy>
					<ixz>0</ixz>
					<iyy>0.001</iyy>
					<iyz>0</iyz>
					<izz>0.001</izz>
				</inertia>
			</inertial>
			<visual name="whiskeye_head_1_row_mini_6_whiskerasm_soc_100mm_1.dae_visual">
				<pose>0 0 0 0 0 0</pose>
				<geometry>
					<mesh>
						<uri>model://robot/mesh/hi/whiskeye_head_1_row_mini_6_whiskerasm_soc_100mm_1.dae</uri>
					</mesh>
				</geometry>
				<material>
					<ambient>0.1 0.1 0.1 1</ambient>
					<diffuse>0.1 0.1 0.1 1</diffuse>
					<specular>0.1 0.1 0.1 1</specular>
				</material>
			</visual>


			<collision name="whiskeye_head_1_row_mini_6_whiskerasm_soc_100mm_1.dae_collision">
				<pose>0 0 0 0 0 0</pose>
				<geometry>
					<mesh>
						<uri>model://robot/mesh/lo/whiskeye_head_1_row_mini_6_whiskerasm_soc_100mm_1.dae</uri>
					</mesh>
				</geometry>
				<surface>
					<friction>
						<ode>
							<mu>0.1</mu>
							<mu2>0.1</mu2>
						</ode>
					</friction>
					<contact>
						<collide_without_contact>1</collide_without_contact>
					</contact>
				</surface>
			</collision>

			<sensor name="whisker6_1_contact" type="contact">
				<contact>
					<collision>whiskeye_head_1_row_mini_6_whiskerasm_soc_100mm_1.dae_collision</collision>
				</contact>
				<always_on>1</always_on>
				<update_rate>50</update_rate>
				<visualize>false</visualize>
			</sensor>

		</link>

		<joint type="revolute" name="head_whisker6_2">
			<pose>0.205115273595 0.0787149518728 0.567241489887 0 0 0</pose>
			<parent>head</parent>
			<child>whisker6_2</child>
			<axis>
				<xyz>0.000987568986602 -0.000156190537382 1.76696848939e-05</xyz>
				<limit>
					<lower>-1.0471975511965976</lower>
					<upper>1.0471975511965976</upper>
				</limit>
				<dynamics>
					<friction>0.1</friction>
					<damping>0.1</damping>
				</dynamics>
			</axis>
		</joint>

		<link name="whisker6_2">
			<inertial>
				<pose>0.205115273595 0.0787149518728 0.567241489887 0 0 0</pose>
				<mass>0.01</mass>
				<inertia>
					<ixx>0.001</ixx>
					<ixy>0</ixy>
					<ixz>0</ixz>
					<iyy>0.001</iyy>
					<iyz>0</iyz>
					<izz>0.001</izz>
				</inertia>
			</inertial>
			<visual name="whiskeye_head_1_row_mini_6_whiskerasm_soc_150mm_1.dae_visual">
				<pose>0 0 0 0 0 0</pose>
				<geometry>
					<mesh>
						<uri>model://robot/mesh/hi/whiskeye_head_1_row_mini_6_whiskerasm_soc_150mm_1.dae</uri>
					</mesh>
				</geometry>
				<material>
					<ambient>0.1 0.1 0.1 1</ambient>
					<diffuse>0.1 0.1 0.1 1</diffuse>
					<specular>0.1 0.1 0.1 1</specular>
				</material>
			</visual>

			<collision name="whiskeye_head_1_row_mini_6_whiskerasm_soc_150mm_1.dae_collision">
				<pose>0 0 0 0 0 0</pose>
				<geometry>
					<mesh>
						<uri>model://robot/mesh/lo/whiskeye_head_1_row_mini_6_whiskerasm_soc_150mm_1.dae</uri>
					</mesh>
				</geometry>
				<surface>
					<friction>
						<ode>
							<mu>0.1</mu>
							<mu2>0.1</mu2>
						</ode>
					</friction>
					<contact>
						<collide_without_contact>1</collide_without_contact>
					</contact>
				</surface>
			</collision>

			<sensor name="whisker6_2_contact" type="contact">
				<contact>
					<collision>whiskeye_head_1_row_mini_6_whiskerasm_soc_150mm_1.dae_collision</collision>
				</contact>
				<always_on>1</always_on>
				<update_rate>50</update_rate>
				<visualize>false</visualize>
			</sensor>

		</link>

		<joint type="revolute" name="head_whisker6_3">
			<pose>0.20807236433 0.0910063236952 0.554411292076 0 0 0</pose>
			<parent>head</parent>
			<child>whisker6_3</child>
			<axis>
				<xyz>0.00098143145442 -0.000190998063772 -1.766967398e-05</xyz>
				<limit>
					<lower>-1.0471975511965976</lower>
					<upper>1.0471975511965976</upper>
				</limit>
				<dynamics>
					<friction>0.1</friction>
					<damping>0.1</damping>
				</dynamics>
			</axis>
		</joint>

		<link name="whisker6_3">
			<inertial>
				<pose>0.20807236433 0.0910063236952 0.554411292076 0 0 0</pose>
				<mass>0.01</mass>
				<inertia>
					<ixx>0.001</ixx>
					<ixy>0</ixy>
					<ixz>0</ixz>
					<iyy>0.001</iyy>
					<iyz>0</iyz>
					<izz>0.001</izz>
				</inertia>
			</inertial>
			<visual name="whiskeye_head_1_row_mini_6_whiskerasm_soc_220mm_1.dae_visual">
				<pose>0 0 0 0 0 0</pose>
				<geometry>
					<mesh>
						<uri>model://robot/mesh/hi/whiskeye_head_1_row_mini_6_whiskerasm_soc_220mm_1.dae</uri>
					</mesh>
				</geometry>
				<material>
					<ambient>0.1 0.1 0.1 1</ambient>
					<diffuse>0.1 0.1 0.1 1</diffuse>
					<specular>0.1 0.1 0.1 1</specular>
				</material>
			</visual>

			<collision name="whiskeye_head_1_row_mini_6_whiskerasm_soc_220mm_1.dae_collision">
				<pose>0 0 0 0 0 0</pose>
				<geometry>
					<mesh>
						<uri>model://robot/mesh/lo/whiskeye_head_1_row_mini_6_whiskerasm_soc_220mm_1.dae</uri>
					</mesh>
				</geometry>
				<surface>
					<friction>
						<ode>
							<mu>0.1</mu>
							<mu2>0.1</mu2>
						</ode>
					</friction>
					<contact>
						<collide_without_contact>1</collide_without_contact>
					</contact>
				</surface>
			</collision>

			<sensor name="whisker6_3_contact" type="contact">
				<contact>
					<collision>whiskeye_head_1_row_mini_6_whiskerasm_soc_220mm_1.dae_collision</collision>
				</contact>
				<always_on>1</always_on>
				<update_rate>50</update_rate>
				<visualize>false</visualize>
			</sensor>

		</link>

		<joint type="revolute" name="head_whisker6_4">
			<pose>0.210938990116 0.102940492332 0.541189789772 0 0 0</pose>
			<parent>head</parent>
			<child>whisker6_4</child>
			<axis>
				<xyz>0.000972866429947 -0.000225242518354 -5.28869422851e-05</xyz>
				<limit>
					<lower>-1.0471975511965976</lower>
					<upper>1.0471975511965976</upper>
				</limit>
				<dynamics>
					<friction>0.1</friction>
					<damping>0.1</damping>
				</dynamics>
			</axis>
		</joint>

		<link name="whisker6_4">
			<inertial>
				<pose>0.210938990116 0.102940492332 0.541189789772 0 0 0</pose>
				<mass>0.01</mass>
				<inertia>
					<ixx>0.001</ixx>
					<ixy>0</ixy>
					<ixz>0</ixz>
					<iyy>0.001</iyy>
					<iyz>0</iyz>
					<izz>0.001</izz>
				</inertia>
			</inertial>
			<visual name="whiskeye_head_1_row_mini_6_whiskerasm_soc_300mm_1.dae_visual">
				<pose>0 0 0 0 0 0</pose>
				<geometry>
					<mesh>
						<uri>model://robot/mesh/hi/whiskeye_head_1_row_mini_6_whiskerasm_soc_300mm_1.dae</uri>
					</mesh>
				</geometry>
				<material>
					<ambient>0.1 0.1 0.1 1</ambient>
					<diffuse>0.1 0.1 0.1 1</diffuse>
					<specular>0.1 0.1 0.1 1</specular>
				</material>
			</visual>

			<collision name="whiskeye_head_1_row_mini_6_whiskerasm_soc_300mm_1.dae_collision">
				<pose>0 0 0 0 0 0</pose>
				<geometry>
					<mesh>
						<uri>model://robot/mesh/lo/whiskeye_head_1_row_mini_6_whiskerasm_soc_300mm_1.dae</uri>
					</mesh>
				</geometry>
				<surface>
					<friction>
						<ode>
							<mu>0.1</mu>
							<mu2>0.1</mu2>
						</ode>
					</friction>
					<contact>
						<collide_without_contact>1</collide_without_contact>
					</contact>
				</surface>
			</collision>

			<sensor name="whisker6_4_contact" type="contact">
				<contact>
					<collision>whiskeye_head_1_row_mini_6_whiskerasm_soc_300mm_1.dae_collision</collision>
				</contact>
				<always_on>1</always_on>
				<update_rate>50</update_rate>
				<visualize>false</visualize>
			</sensor>

		</link>

		<joint type="prismatic" name="pose_x">
			<pose>0 0 0 0 0 0</pose>
			<parent>world</parent>
			<child>link_pose_x</child>
			<axis>
				<xyz>1 0 0</xyz>
				<dynamics>
					<friction>0.0</friction>
					<damping>0.0</damping>
				</dynamics>
			</axis>
		</joint>

		<plugin
			filename="gz-sim-joint-controller-system"
			name="gz::sim::systems::JointController">
			<joint_name>pose_x</joint_name>
			<topic>/whiskeye/pose_x/vel_cmd</topic>
			<p_gain>5000.0</p_gain>
			<i_gain>0.0</i_gain>
			<d_gain>0.0</d_gain>
			<i_max>5000.0</i_max>
			<i_min>-5000.0</i_min>
			<cmd_max>2500</cmd_max>
			<cmd_min>-2500</cmd_min>
		</plugin>

		<link name="link_pose_x">
			<inertial>
				<pose>0 0 0 0 0 0</pose>
				<mass>0.0001 </mass>
				<inertia>
					<ixx>0.1</ixx>
					<ixy>0</ixy>
					<ixz>0</ixz>
					<iyy>0.1</iyy>
					<iyz>0</iyz>
					<izz>0.1</izz>
				</inertia>
			</inertial>
		</link>

		<joint type="prismatic" name="pose_y">
			<pose>0 0 0 0 0 0</pose>
			<parent>link_pose_x</parent>
			<child>link_pose_y</child>
			<axis>
				<xyz>0 1 0</xyz>
				<dynamics>
					<friction>0.0</friction>
					<damping>0.0</damping>
				</dynamics>
			</axis>
		</joint>

		<plugin
			filename="gz-sim-joint-controller-system"
			name="gz::sim::systems::JointController">
			<joint_name>pose_y</joint_name>
			<topic>/whiskeye/pose_y/vel_cmd</topic>
			<p_gain>5000.0</p_gain>
			<i_gain>0.0</i_gain>
			<d_gain>0.0</d_gain>
			<i_max>5000.0</i_max>
			<i_min>-5000.0</i_min>
			<cmd_max>2500</cmd_max>
			<cmd_min>-2500</cmd_min>
		</plugin>

		<link name="link_pose_y">
			<inertial>
				<pose>0 0 0 0 0 0</pose>
				<mass>0.0001 </mass>
				<inertia>
					<ixx>0.1</ixx>
					<ixy>0</ixy>
					<ixz>0</ixz>
					<iyy>0.1</iyy>
					<iyz>0</iyz>
					<izz>0.1</izz>
				</inertia>
			</inertial>
		</link>

		<joint type="prismatic" name="pose_z">
			<pose>0 0 0 0 0 0</pose>
			<parent>link_pose_y</parent>
			<child>link_pose_z</child>
			<axis>
				<xyz>0 0 1</xyz>
				<dynamics>
					<friction>0.0</friction>
					<damping>0.0</damping>
				</dynamics>
			</axis>
		</joint>

		<link name="link_pose_z">
			<inertial>
				<pose>0 0 0 0 0 0</pose>
				<mass>0.0001</mass>
				<inertia>
					<ixx>0.1</ixx>
					<ixy>0</ixy>
					<ixz>0</ixz>
					<iyy>0.1</iyy>
					<iyz>0</iyz>
					<izz>0.1</izz>
				</inertia>
			</inertial>
		</link>

		<joint type="revolute" name="pose_theta">
			<pose>0 0 0 0 0 0</pose>
			<parent>link_pose_z</parent>
			<child>body</child>
			<axis>
				<xyz>0 0 1</xyz>
				<dynamics>
					<friction>0.0</friction>
					<damping>0.0</damping>
				</dynamics>
			</axis>
		</joint>

		<plugin
			filename="gz-sim-joint-controller-system"
			name="gz::sim::systems::JointController">
			<joint_name>pose_theta</joint_name>
			<topic>/whiskeye/pose_theta/vel_cmd</topic>
			<p_gain>1000.0</p_gain>
			<i_gain>0.0</i_gain>
			<d_gain>0.0</d_gain>
			<i_max>1000.0</i_max>
			<i_min>-1000.0</i_min>
			<cmd_max>500</cmd_max>
			<cmd_min>-500</cmd_min>
		</plugin>

	</model>
</sdf>
